File: data/experiment/compare.csv
Experiment:,25C,,,,,,,,,,,,,,New3D,,New2D,,,1.94E-01,9811.8,,,,,,,,,,,,,,,,,,,,,,,,,,,,,,,,,,,,,,,,,,,,,,,,,,,,,
Time (s),Depth (nm),Load (uN),,hm (nm),F (uN),hm1 (um),hm1 (nm),F1 (uN),F (exp),disp_y_2D,react_y_2D,disp_y_3D,react_y_3D,,h3D,F3D,h2D,F2D,,Depth1,Force1,Depth2,Force2,Depth,Force,,Depth0 (nm),Load0 (uN),Depth2 (nm),Load2 (uN),Depth3 (nm),Load3 (uN),Depth4 (nm),Load4 (uN),Depth5 (nm),Load5 (uN),Depth6 (nm),Load6 (uN),Depth7 (nm),Load7 (uN),Depth8 (nm),Load8 (uN),Depth9 (nm),Load9 (uN),Depth10 (nm),Load10 (uN),Depth11 (nm),Load11 (uN),Depth12 (nm),Load12 (uN),Depth13 (nm),Load13 (uN),Depth14 (nm),Load14 (uN),Depth15 (nm),Load15 (uN),Depth16 (nm),Load16 (uN),Depth17 (nm),Load17 (uN),Depth18 (nm),Load18 (uN),Depth19 (nm),Load19 (uN),Depth20 (nm),Load20 (uN),Depth21 (nm),Load21 (uN),Depth22 (nm),Load22 (uN),Depth23 (nm),Load23 (uN),Depth24 (nm),Load24 (uN)
4.081254,0,0.828354,,0,5.49E-13,0.00E+00,0.00E+00,1.80E-11,0,0,0,0,0,,-2.22E-03,9.54E+00,,,,1.95E-03,4.5827,1.84E-03,6.7346,1.21E-03,1.5464,,0,-4.364263,0,3.796191,0,3.084887,0,4.773295,0,5.270559,0,2.265517,0,1.745296,0,4.040522,0,4.948084,0,3.36237,0,5.992596,0,4.908226,0,6.264292,0,4.128094,0,3.081519,0,3.360005,0,1.739676,0,0.628085,0,0.516542,0,4.915756,0,0.750495,0,0.823302,0,2.771492,0,4.984049
4.386547,20.040846,259.018955,,115.65,3266.9,1.25E-01,1.25E+02,3074.8,4223.823271,-0.13786,-3.826906043,-0.13786,-0.650232258,,-0.13764,4168.8,,,,0.11938,3850.7,0.128,4582.4,0.12814,3868.3,,15.217825,255.39271,16.616722,258.612018,18.92569,258.407202,18.284076,258.539213,16.643971,258.57909,19.33078,258.39153,17.290373,258.476677,15.083952,258.493172,14.543286,258.566295,16.874676,258.474301,14.646612,258.63202,15.000263,258.682415,18.032486,258.511645,16.772108,258.468378,14.792148,258.554322,16.135553,258.682084,16.133647,258.817005,16.092501,258.648489,17.910218,258.315533,16.79177,258.528244,16.07662,258.424513,16.693541,258.494148,15.164397,258.585978,14.328989,258.757421
4.69184,34.30589,582.330233,,143.88,675.26,1.39E-01,1.39E+02,450.55,0,,,,,,,,,,,0.12628,762.03,0.13536,910,0.13536,795.48,,25.776442,578.180913,27.672243,582.103949,39.243507,582.028285,38.105783,582.156966,27.107025,582.175625,34.833673,582.039774,39.44677,582.076691,26.07475,582.071125,25.166911,582.147358,37.363553,582.130887,25.1442,582.194314,25.924437,582.228615,34.296619,582.091761,36.788203,582.093014,25.270865,582.159645,26.680455,582.236069,36.798106,582.17637,26.300837,582.198581,36.093603,582.034934,32.609999,581.989308,26.461562,582.094589,37.839052,582.076502,25.610263,582.184442,24.294646,582.276543
4.997133,45.84146,893.507434,,,,,,,,,,,,,,,,,,,,,33.706897,889.508359,36.033437,893.339224,52.929814,893.219255,52.400821,893.355136,35.252403,893.388607,46.956593,893.285531,53.380226,893.385214,33.890732,893.348798,33.682303,893.366891,50.496012,893.37213,33.499557,893.410922,34.560383,893.431396,46.593302,893.347138,49.170745,893.328633,33.392876,893.387084,35.081369,893.410702,50.551443,893.440172,33.846696,893.458795,52.168251,893.232259,43.97082,893.289253,34.025835,893.400375,51.106469,893.34431,34.098869,893.335048,32.25389,893.481691,,,,
5.302426,55.603863,1202.094544,,,,,,,,,,,,,,,,,,,,,40.612908,1198.271007,50.466607,1201.110101,64.022559,1201.906786,63.205865,1201.963507,42.144538,1202.02287,57.07545,1201.919816,64.793484,1201.996831,46.761412,1201.973618,40.494386,1201.973235,61.499502,1201.992764,46.925025,1201.99235,47.449105,1201.282967,56.859295,1201.994975,61.026284,1201.931214,40.291885,1201.994215,42.069153,1202.041684,62.125886,1201.983403,40.838394,1202.032306,62.496929,1201.931508,53.97257,1201.982497,41.353854,1201.96316,63.072254,1201.958785,40.918309,1201.958047,39.127339,1202.055359,,,,
5.607718,64.262027,1509.592428,,,,,,,,,,,,,,,,,,,,,46.62825,1505.967714,57.830941,1509.43073,74.81326,1509.396037,73.222935,1509.496644,55.355134,1509.465227,66.867014,1509.382805,76.136102,1509.532004,54.141556,1509.40173,53.79844,1509.404326,71.99798,1509.467979,54.070553,1509.480981,56.894236,1509.543048,67.444786,1509.510176,70.705648,1509.43653,46.639845,1509.475776,57.347164,1509.521102,72.807524,1509.507172,47.357407,1509.486864,73.203742,1509.419137,62.904676,1509.396327,55.508574,1509.42648,73.367336,1509.51135,47.075234,1509.487075,44.85822,1509.581847,,,,
5.913011,72.079736,1816.42894,,,,,,,,,,,,,,,,,,,,,52.444447,1813.036463,66.330318,1816.222036,84.284462,1816.292642,83.144286,1816.325555,62.086112,1816.342348,76.12213,1816.279996,85.253565,1816.382972,60.626473,1816.302421,61.378815,1816.284903,82.326226,1816.337845,61.984525,1816.344275,64.4392,1816.379422,76.359495,1816.325732,80.915651,1816.301324,61.716972,1816.34003,64.352047,1816.396286,82.855282,1816.373082,61.356749,1816.33567,83.810148,1816.274463,72.105658,1816.282792,62.051099,1816.31562,82.779405,1816.310665,60.139952,1816.32335,59.076656,1816.364543,,,,
6.218304,80.28621,2122.898034,,,,,,,,,,,,,,,,,,,,,68.646897,2119.121705,73.83531,2122.779625,93.009081,2122.789769,91.017227,2122.861465,69.346658,2122.839743,84.985334,2122.787773,95.101356,2122.845433,67.099417,2122.787824,68.075262,2122.840167,89.986661,2122.841922,70.075598,2122.86269,71.798305,2122.887012,84.075811,2122.833444,89.274959,2122.831159,68.281861,2122.836121,71.816507,2122.89088,93.141077,2122.828028,67.093628,2122.849131,92.931815,2122.783607,79.990382,2122.82169,68.361318,2122.83388,91.505657,2122.855361,66.827244,2122.821538,65.0331,2122.878698,,,,
6.523597,87.052433,2429.16601,,,,,,,,,,,,,,,,,,,,,73.165069,2426.222489,80.521362,2429.07303,101.618405,2429.054344,100.312426,2429.143657,75.291039,2429.119394,92.691569,2429.03472,103.729567,2429.15509,75.252018,2429.063346,74.772348,2429.067397,97.887448,2429.149171,75.918313,2429.138655,77.800188,2429.164246,92.212927,2429.125029,97.31756,2429.109141,74.336874,2429.122754,78.59738,2429.125559,102.167782,2429.072055,73.068469,2429.133226,100.922153,2429.065322,87.334452,2429.056284,74.746843,2429.10071,100.158592,2429.146261,72.561304,2429.081135,71.712357,2429.146583,,,,
6.82889,93.511723,2735.126552,,,,,,,,,,,,,,,,,,,,,80.640844,2732.408779,88.84479,2735.062499,110.048119,2735.031308,107.402299,2735.133575,81.491529,2735.147977,100.440589,2735.075179,111.822195,2735.136932,80.977116,2735.089806,80.946762,2735.114088,106.791367,2735.120412,81.840248,2735.158666,84.19713,2735.153331,100.117346,2735.124331,106.697978,2735.099055,80.21571,2735.153016,84.642411,2735.194289,110.060953,2735.086083,79.333517,2735.102113,109.608998,2735.083206,94.058643,2735.075108,83.472422,2735.12775,107.67253,2735.095305,77.744865,2735.132685,77.636787,2735.156707,,,,
7.134182,100.426802,3041.039148,,,,,,,,,,,,,,,,,,,,,86.016701,3038.556245,95.66167,3040.960707,117.845755,3040.959601,115.183771,3041.014681,87.960735,3040.952552,107.355714,3040.97525,120.991895,3041.008105,87.506981,3040.957921,86.348415,3040.9808,116.081718,3041.002333,89.694054,3040.96206,90.09795,3041.032731,107.165641,3041.003558,114.188242,3041.007116,85.809832,3040.969379,90.226844,3041.034311,116.865062,3041.037697,84.89248,3040.994477,117.008055,3040.992143,100.129516,3040.944018,88.788731,3040.95994,115.306243,3040.975936,83.960538,3040.984422,84.450947,3040.979096,,,,
7.439475,106.201118,3346.852346,,,,,,,,,,,,,,,,,,,,,90.847472,3344.603053,102.867262,3346.765768,125.156717,3346.774068,123.81275,3346.839925,93.102982,3346.808214,114.665831,3346.767771,128.576352,3346.846563,92.786186,3346.740506,91.967655,3346.780269,122.653273,3346.84217,94.613348,3346.799706,96.633527,3346.824557,113.973235,3346.831047,121.328481,3346.769499,91.500148,3346.792402,95.931892,3346.819334,124.808744,3346.841553,90.441339,3346.810186,125.632551,3346.789054,106.704791,3346.811072,93.952028,3346.76032,123.217068,3346.811447,89.472443,3346.768647,89.668438,3346.829421,,,,
7.744768,113.490625,3652.575275,,,,,,,,,,,,,,,,,,,,,95.996485,3650.540187,112.06541,3652.506231,133.00364,3652.497733,130.813824,3652.574316,100.230393,3652.513413,120.928583,3652.50581,135.814112,3652.539196,97.785719,3652.504458,97.615943,3652.47649,130.529682,3652.515843,99.98091,3652.549612,105.926451,3652.544315,120.252419,3652.524492,129.859434,3652.529406,96.480518,3652.5159,101.060439,3652.55192,132.634627,3652.529665,96.103636,3652.531655,132.801363,3652.530482,112.593515,3652.507739,99.248519,3652.51279,130.153783,3652.536151,96.80391,3652.503481,94.812675,3652.534825,,,,
8.050061,120.082639,3958.234961,,,,,,,,,,,,,,,,,,,,,100.984376,3956.396007,119.461225,3958.174145,139.175033,3958.165319,137.823881,3958.212502,105.462796,3958.217393,128.630134,3958.165146,141.678009,3958.205367,103.650395,3958.153506,102.22236,3958.197333,137.813147,3958.160873,105.904215,3958.216249,111.449112,3958.240265,125.964923,3958.175532,138.591454,3958.183715,101.793856,3958.187239,108.014074,3958.159921,140.069495,3958.226358,101.098397,3958.211775,139.708046,3958.196683,118.500363,3958.189278,105.447868,3958.17558,138.102999,3958.195714,101.881935,3958.192926,100.903897,3958.231812,,,,
8.355354,125.695113,4263.835367,,,,,,,,,,,,,,,,,,,,,106.007356,4262.234579,126.754091,4263.813514,146.610811,4263.805441,144.458887,4263.842065,110.578839,4263.891252,134.392703,4263.838135,149.193552,4263.866252,108.653913,4263.88226,106.768784,4263.878896,143.966219,4263.831385,111.264252,4263.87631,117.258594,4263.873331,132.708273,4263.849279,144.514417,4263.823033,107.526816,4263.877674,114.601158,4263.855057,146.963307,4263.84035,107.809861,4263.870333,147.119603,4263.832616,124.538591,4263.837714,110.573164,4263.83184,145.759237,4263.829682,106.519147,4263.855956,105.799854,4263.914178,,,,
8.660647,131.113754,4569.457349,,,,,,,,,,,,,,,,,,,,,110.712309,4568.069541,132.655164,4569.446877,153.498805,4569.40132,151.474479,4569.430863,115.181484,4569.394098,141.087348,4569.416577,155.972344,4569.461875,115.238242,4569.380244,112.046373,4569.427854,151.291743,4569.425537,116.342144,4569.406014,122.322342,4569.455148,138.765784,4569.435265,151.124251,4569.446404,111.775531,4569.391558,119.251577,4569.436556,153.922734,4569.427926,112.476418,4569.376089,154.036406,4569.406995,130.879266,4569.420632,116.307059,4569.38568,151.907539,4569.429697,111.013056,4569.40649,110.37281,4569.409529,,,,
8.965939,136.438901,4874.927049,,,,,,,,,,,,,,,,,,,,,115.367776,4873.739789,139.259692,4874.919293,160.216331,4874.859906,158.01035,4874.931934,119.996194,4874.940033,147.595177,4874.920665,162.662882,4874.917988,121.959179,4874.910126,116.871769,4874.946257,158.284711,4874.935548,121.205039,4874.924899,127.445975,4874.955836,144.356378,4874.932943,157.079005,4874.939901,115.981455,4874.948579,123.65713,4874.958821,159.71718,4874.905729,116.282381,4874.956378,162.010605,4874.899506,135.957515,4874.924107,120.87099,4874.95598,157.365282,4874.957384,115.434871,4874.955916,115.904075,4874.962357,,,,
9.271232,141.336933,5180.441147,,,,,,,,,,,,,,,,,,,,,119.495679,5179.526362,145.393171,5180.408316,166.659736,5180.398753,163.911268,5180.416358,124.914006,5180.409351,153.345746,5180.403403,168.857475,5180.465184,126.327688,5180.400706,122.38359,5180.417446,164.401487,5180.446199,127.926564,5180.382169,132.67434,5180.421627,149.827146,5180.431924,163.786243,5180.422218,120.379575,5180.362683,128.297323,5180.425557,165.672561,5180.45718,121.604099,5180.410564,168.475266,5180.413922,140.579314,5180.420981,125.742099,5180.36342,164.239996,5180.453986,119.589501,5180.384836,121.843622,5180.401973,,,,
9.576525,146.888814,5485.87809,,,,,,,,,,,,,,,,,,,,,125.280163,5485.12054,151.233136,5485.858348,172.642304,5485.838108,169.443677,5485.842292,130.283639,5485.879598,159.982854,5485.894876,175.47093,5485.84054,131.280731,5485.844042,130.116644,5485.853815,170.565091,5485.837786,133.539121,5485.882159,137.345123,5485.863749,154.730758,5485.860146,169.704711,5485.882139,124.696242,5485.900905,133.674377,5485.862699,171.449681,5485.828729,127.692772,5485.859007,174.437868,5485.836005,146.262264,5485.842034,130.059204,5485.88997,171.323709,5485.824369,123.971922,5485.874469,126.075449,5485.889787,,,,
9.881818,152.012002,5791.309731,,,,,,,,,,,,,,,,,,,,,129.745193,5790.816127,157.623887,5791.254522,178.796701,5791.288748,176.66478,5791.295582,134.699926,5791.277703,165.936757,5791.238153,181.533325,5791.288438,135.480363,5791.25072,134.898466,5791.268388,176.477107,5791.309348,138.50471,5791.262071,142.038214,5791.302749,161.360238,5791.285861,175.722966,5791.26497,128.825697,5791.281206,138.335693,5791.295882,178.319402,5791.301341,132.465348,5791.274415,179.899898,5791.284331,151.872517,5791.299642,135.308533,5791.24924,178.646015,5791.286443,128.81669,5791.295919,132.38721,5791.293564,,,,
10.187111,157.032172,6096.802025,,,,,,,,,,,,,,,,,,,,,134.74398,6096.530873,163.318993,6096.821765,183.587491,6096.828517,182.857461,6096.828507,139.595455,6096.790414,171.624977,6096.797169,187.338067,6096.788649,139.980981,6096.806093,139.039314,6096.799496,182.071104,6096.764113,143.192587,6096.819044,146.713798,6096.779771,166.346477,6096.780315,181.051604,6096.75183,135.360447,6096.760632,143.112765,6096.779493,184.461865,6096.808123,137.421878,6096.791745,186.432422,6096.789056,156.881395,6096.751403,139.772549,6096.76859,183.748985,6096.784283,133.146572,6096.765341,136.846341,6096.779595,,,,
10.492403,162.065798,6402.285636,,,,,,,,,,,,,,,,,,,,,139.315146,6402.202652,169.612104,6402.29461,188.755544,6402.261066,188.526812,6402.293177,143.812877,6402.238862,177.573038,6402.259646,192.925286,6402.241451,144.894375,6402.216238,142.911617,6402.239887,188.417814,6402.264399,148.285276,6402.271772,151.421015,6402.244379,172.030711,6402.245936,186.481748,6402.267431,139.483466,6402.271061,148.680929,6402.265783,190.447155,6402.279808,142.653661,6402.255065,192.85038,6402.285473,161.552993,6402.272863,144.231659,6402.27489,189.122203,6402.262394,136.844368,6402.277456,140.475561,6402.256028,,,,
10.797696,166.742104,6707.585862,,,,,,,,,,,,,,,,,,,,,144.629311,6707.774893,174.907746,6707.58502,195.0685,6707.603621,193.233487,6707.6007,149.179634,6707.605287,183.65627,6707.561575,198.323093,6707.590235,148.770509,6707.587201,146.811637,6707.577307,194.209371,6707.593129,152.502698,6707.56174,156.074443,6707.572409,177.210368,6707.603241,192.23987,6707.572828,144.034159,6707.566135,153.04236,6707.572087,197.634554,6707.61046,146.358126,6707.561727,198.428306,6707.588236,166.369013,6707.574893,150.094545,6707.57685,195.019449,6707.598956,141.452822,6707.57325,144.544381,6707.562593,,,,
11.102989,171.475086,7012.969766,,,,,,,,,,,,,,,,,,,,,149.555482,7013.402401,179.577114,7012.964726,202.220027,7013.005823,198.920041,7012.9837,154.710429,7012.994482,189.125834,7012.985311,204.109638,7012.950648,153.112587,7012.965303,150.954777,7012.96477,199.177455,7012.986466,157.64584,7012.992518,160.992335,7012.982194,181.940085,7012.992261,197.789888,7012.983557,150.188907,7012.975859,157.966568,7012.949537,202.842662,7012.989979,150.860867,7012.95256,204.076642,7012.990434,171.424268,7012.970405,153.83001,7012.96562,201.562335,7012.943118,146.620284,7012.961809,149.04362,7012.968971,,,,
11.408282,176.315499,7318.289131,,,,,,,,,,,,,,,,,,,,,153.759016,7318.874043,184.411262,7318.328674,207.04484,7318.301255,204.397814,7318.31686,159.109014,7318.285433,193.837892,7318.271702,209.296352,7318.301005,157.111321,7318.316769,155.001412,7318.252344,204.255398,7318.262735,161.873216,7318.2858,165.682341,7318.298827,186.686815,7318.248319,203.250021,7318.299572,154.119302,7318.285682,164.572385,7318.307047,207.224275,7318.2996,155.340976,7318.271509,210.228797,7318.302355,176.799692,7318.315996,158.354032,7318.30906,207.147743,7318.282554,152.072253,7318.281385,153.420593,7318.285868,,,,
11.713575,182.305704,7623.724486,,,,,,,,,,,,,,,,,,,,,158.152486,7624.575744,189.602284,7623.718935,212.306006,7623.756832,209.707502,7623.726832,163.481168,7623.784798,199.800482,7623.735742,216.001085,7623.744779,161.979461,7623.774662,159.678133,7623.784424,209.023011,7623.743325,166.106295,7623.714058,170.19915,7623.721535,191.477466,7623.764923,208.595496,7623.731015,159.223417,7623.755747,168.575805,7623.74015,212.818266,7623.798296,159.555218,7623.742717,215.122576,7623.703462,180.956224,7623.711547,162.757717,7623.7797,212.81818,7623.719099,156.49675,7623.751888,157.916457,7623.71655,,,,
12.018867,188.326716,7929.017403,,,,,,,,,,,,,,,,,,,,,162.327002,7930.093885,194.312488,7929.073179,217.649058,7929.068793,215.375015,7929.049938,167.341326,7929.056618,204.691903,7929.090354,220.966732,7929.079184,165.501105,7929.087439,163.568417,7929.038337,215.439062,7929.068863,171.251104,7929.065549,175.51535,7929.003782,195.504124,7929.057893,214.060316,7929.069026,163.899692,7929.075378,172.664013,7929.002511,217.847743,7929.043257,163.610556,7929.069502,220.311012,7929.129142,185.54693,7929.080194,166.659046,7929.06405,218.126215,7929.091278,160.553145,7929.111541,162.495114,7929.091059,,,,
12.32416,193.553131,8234.351017,,,,,,,,,,,,,,,,,,,,,166.428501,8235.640163,200.296379,8234.404491,222.692182,8234.369051,219.606727,8234.341604,171.4055,8234.332343,209.254961,8234.356666,226.200752,8234.420387,169.880573,8234.421142,167.360668,8234.372898,220.449009,8234.382061,175.750787,8234.382245,181.079937,8234.371932,200.379284,8234.400616,219.727623,8234.406922,167.757397,8234.385161,177.512374,8234.37492,223.197286,8234.338066,167.725104,8234.442751,224.387892,8234.409124,190.133148,8234.413694,170.875233,8234.41949,223.378509,8234.435525,164.336751,8234.359625,166.365913,8234.371508,,,,
12.629453,197.652557,8539.646732,,,,,,,,,,,,,,,,,,,,,170.13731,8541.23568,205.180908,8539.741322,228.142505,8539.79455,224.730568,8539.698722,175.911603,8539.709543,214.219024,8539.735971,232.055993,8539.714315,173.519596,8539.763121,171.281659,8539.726544,227.076042,8539.760468,180.188815,8539.750859,185.770368,8539.705372,204.79602,8539.766294,224.764346,8539.744767,171.542444,8539.681407,182.541888,8539.719165,229.023919,8539.777274,171.524802,8539.708537,231.137173,8539.738075,193.603432,8539.689747,174.840797,8539.71013,228.150565,8539.723461,168.762933,8539.691022,170.773055,8539.658968,,,,
12.934746,203.046089,8845.022178,,,,,,,,,,,,,,,,,,,,,173.605185,8846.748545,210.540427,8845.126828,233.252272,8845.109927,230.49685,8845.064437,180.040344,8845.064044,218.598108,8845.107247,236.942402,8845.025386,177.977325,8845.070325,174.609836,8845.066584,233.284803,8845.059016,184.445028,8845.049439,190.2479,8845.073544,209.043766,8845.10979,230.798038,8845.063238,175.608119,8845.05656,187.014657,8845.057368,233.787129,8845.109226,175.682886,8845.036808,236.917376,8845.098102,198.32369,8845.067919,178.282811,8845.06465,233.750297,8845.096211,172.951232,8845.106238,175.086903,8845.016356,,,,
13.240039,207.609928,9150.314537,,,,,,,,,,,,,,,,,,,,,177.794667,9152.267595,214.656635,9150.361016,238.615021,9150.369662,235.695853,9150.297702,184.043084,9150.354631,222.835214,9150.360949,241.933402,9150.29306,181.830682,9150.389965,178.620687,9150.368792,239.012447,9150.344252,188.472708,9150.340237,194.781903,9150.321787,213.33474,9150.311304,235.532056,9150.405491,179.743666,9150.340212,190.701179,9150.335986,238.89721,9150.390318,180.126524,9150.399382,242.30932,9150.368615,202.673616,9150.415643,183.838709,9150.42333,238.609698,9150.279037,176.654656,9150.353022,181.17094,9150.325056,,,,
13.545331,212.034077,9455.643223,,,,,,,,,,,,,,,,,,,,,181.464322,9457.887014,219.379966,9455.759307,243.878585,9455.795772,240.256218,9455.71864,188.156999,9455.77469,227.036701,9455.732013,247.172471,9455.695975,185.9774,9455.809158,182.817288,9455.753854,243.901429,9455.645303,192.798677,9455.774302,199.081365,9455.704303,218.385083,9455.776943,240.218256,9455.688231,183.313759,9455.773177,194.893805,9455.740942,244.355971,9455.743544,183.96182,9455.785904,247.271568,9455.752336,206.631955,9455.741864,187.384043,9455.77464,243.876232,9455.702505,180.358802,9455.754503,185.637225,9455.772037,,,,
13.850624,216.876081,9761.00235,,,,,,,,,,,,,,,,,,,,,186.028745,9763.393506,223.367694,9761.09963,248.374373,9761.095817,244.640758,9761.028287,192.082619,9760.981858,232.293387,9761.054234,252.459244,9761.022584,189.572593,9761.026875,187.220681,9761.011105,248.249183,9761.045844,197.024382,9760.994506,203.289475,9760.976623,223.184351,9761.002412,245.183811,9761.028568,187.221169,9761.023494,198.774762,9761.04263,249.608341,9760.999734,187.350081,9760.992716,251.89286,9761.04518,211.14298,9761.058483,191.206754,9760.99644,248.113974,9761.039032,184.334939,9761.020138,190.09269,9760.948071,,,,
14.155917,221.150602,10001.05011,,,,,,,,,,,,,,,,,,,,,189.19676,10003.58555,227.511632,10001.3647,253.00374,10001.14953,249.104983,10000.94301,195.720919,10000.94156,236.713191,10001.30375,257.299589,10000.75654,192.940593,10000.90006,190.406487,10001.01018,251.970609,10001.33179,200.092287,10001.12705,207.597203,10001.17324,226.684082,10001.11218,248.963121,10001.31672,190.318376,10000.78358,202.63242,10000.9454,256.036981,10000.80921,191.092015,10001.35483,256.128744,10000.87405,214.869421,10001.03101,194.956749,10001.1594,251.708215,10001.02673,188.797736,10000.74322,193.377172,10001.16633,,,,
14.46121,222.363159,10000.78326,,,,,,,,,,,,,,,,,,,,,190.140894,10003.58315,228.81266,10001.17496,254.994024,10001.3217,250.707697,10000.84994,197.316332,10001.10915,238.233422,10001.27662,258.610365,10000.8878,194.335099,10000.88624,191.436092,10000.85364,253.08224,10001.22545,201.418996,10000.913,209.071142,10001.29537,227.976121,10000.94183,250.350617,10001.42008,191.343557,10000.86257,204.02373,10001.02515,257.874887,10000.94237,192.077565,10001.25676,258.185207,10000.9524,215.928054,10000.86014,195.758873,10001.2215,254.375657,10000.7961,189.721754,10000.86505,194.987565,10001.26595,,,,
14.766503,223.231875,10000.80855,,,,,,,,,,,,,,,,,,,,,190.755755,10003.7498,229.567063,10001.07483,255.873154,10001.3957,251.190753,10000.86108,198.613837,10001.10556,238.882488,10001.25707,259.61129,10000.97463,195.006645,10000.93134,192.504567,10000.84196,254.095356,10001.0737,201.985725,10000.9078,209.571604,10001.35902,228.629402,10000.90695,251.314542,10001.27382,191.901549,10000.95282,204.333643,10001.08962,258.921609,10000.98153,192.824914,10001.26474,258.546474,10001.00657,216.96782,10000.94488,196.341496,10001.3418,255.097332,10000.83608,190.154288,10001.00798,195.215943,10001.25619,,,,
15.071795,223.712084,10000.83411,,,,,,,,,,,,,,,,,,,,,191.329918,10003.85217,230.311316,10001.04506,256.606508,10001.36551,251.885332,10000.97161,199.610936,10001.30494,239.613698,10001.04205,260.309062,10000.99102,195.889807,10001.01286,192.914555,10000.85047,254.710522,10001.0084,202.845873,10000.73886,210.393397,10001.29774,229.037831,10000.8736,251.881011,10001.3156,192.640283,10000.98368,204.787238,10001.19514,258.963476,10001.12214,193.608375,10001.16131,259.275236,10001.05734,217.463631,10000.90443,196.770167,10001.3235,256.334652,10000.96138,190.343427,10000.93284,195.933396,10001.20339,,,,
15.377088,224.166997,10000.86096,,,,,,,,,,,,,,,,,,,,,191.755251,10003.89593,230.850351,10000.94192,257.190927,10001.39768,252.304803,10001.01676,199.904359,10001.28965,239.825696,10001.16938,260.915995,10001.08123,196.289437,10001.04135,193.180381,10000.85535,255.336658,10000.98401,203.354232,10000.84665,210.899562,10001.26407,229.537425,10000.87164,251.977676,10001.25338,193.098552,10001.06354,205.243931,10001.18016,259.627993,10001.0859,193.249239,10001.29665,259.820004,10001.10314,217.719695,10000.97111,197.415115,10001.324,256.225237,10000.97024,191.01218,10001.03598,196.625897,10001.23162,,,,
15.682381,224.410614,10000.82834,,,,,,,,,,,,,,,,,,,,,192.023012,10003.81492,231.293727,10000.9109,257.687661,10001.32499,252.600702,10001.02023,200.294053,10001.34967,240.829394,10000.9941,261.340458,10001.12428,196.497462,10001.09684,193.491812,10000.96103,255.437353,10001.00039,203.982911,10000.95225,211.301736,10001.20631,229.772038,10000.79562,252.36976,10001.24877,193.251175,10001.10434,205.52623,10001.16236,260.156415,10001.08662,193.811423,10001.15952,260.052986,10001.14299,218.036982,10001.01566,197.717006,10001.3157,256.748182,10001.00269,191.215086,10001.03457,197.03328,10001.22872,,,,
15.987674,224.758151,10000.91657,,,,,,,,,,,,,,,,,,,,,192.427802,10003.84831,231.611275,10000.85856,258.361078,10001.34728,252.869465,10001.08889,200.677162,10001.36681,240.820426,10000.95834,261.692754,10001.14733,196.887155,10001.10992,193.852699,10000.96743,256.206157,10000.78731,204.178994,10000.88266,211.57601,10001.25512,230.06357,10000.7152,252.901066,10001.15308,193.782571,10001.12936,205.847106,10001.22906,260.548825,10001.25617,194.56754,10000.96662,260.84324,10001.16441,218.326879,10001.09392,198.605581,10001.2795,257.331085,10001.06489,191.200601,10001.05417,197.604648,10001.02959,,,,
16.292967,225.100389,10000.95838,,,,,,,,,,,,,,,,,,,,,192.719674,10003.76592,232.101428,10000.77507,258.53776,10001.32955,253.103439,10001.09025,200.86681,10001.32987,241.555314,10000.95037,262.133592,10001.21851,197.003822,10001.15216,194.24785,10001.00356,256.44854,10000.77813,204.612313,10000.94729,211.830488,10001.18854,230.331949,10000.90333,253.266661,10001.08436,193.946513,10001.11808,205.977116,10001.19961,260.621055,10001.17824,194.246495,10000.97986,260.754793,10001.21556,219.188757,10001.11753,199.491426,10001.0945,257.754607,10001.09054,191.456791,10001.06009,197.664333,10001.13228,,,,
16.598259,225.382436,10001.07562,,,,,,,,,,,,,,,,,,,,,192.997931,10003.61812,232.220552,10000.86028,258.976002,10001.17525,253.504438,10001.15424,201.244146,10001.36339,241.729411,10000.9509,262.257364,10001.224,197.047819,10001.1575,194.394919,10001.01801,256.648512,10000.80492,204.22797,10000.79634,212.229227,10001.08818,230.633968,10000.76588,253.435042,10001.13881,194.131943,10001.14259,206.579647,10001.18119,261.426598,10001.26398,194.485959,10001.06416,261.441481,10001.23342,219.302294,10001.13841,199.425039,10001.2745,257.928137,10001.11839,192.083361,10001.06153,198.064014,10001.08639,,,,
16.903552,225.659793,10001.03524,,,,,,,,,,,,,,,,,,,,,193.337696,10003.6612,232.524199,10000.80908,259.206807,10001.09966,253.67197,10001.19539,201.573255,10001.31879,242.388618,10000.90449,262.725719,10001.25661,197.532567,10001.18056,194.600919,10001.021,257.040317,10000.87127,204.755691,10000.89988,212.495418,10001.08792,231.062807,10000.8178,253.677689,10000.96075,194.507906,10001.21487,206.692741,10001.24803,261.682372,10001.32165,194.793751,10000.98327,261.530594,10001.27565,219.578046,10001.11509,199.63427,10001.2685,258.281484,10001.1847,192.286216,10001.10962,198.147491,10000.97147,,,,
17.208845,225.72254,10001.07412,,,,,,,,,,,,,,,,,,,,,193.554921,10003.56582,232.646097,10000.91389,259.511715,10001.17605,253.881554,10001.19449,201.699767,10001.26032,242.618966,10000.87276,262.860851,10001.28613,197.792022,10001.24322,194.819144,10001.10481,257.201971,10000.86428,204.821371,10000.98493,212.835411,10001.07878,230.987628,10000.77475,254.044952,10001.08563,194.791241,10001.23875,206.568143,10001.14917,261.626807,10001.27055,195.387935,10000.91914,261.477901,10001.26361,219.391846,10001.17592,200.214558,10001.1604,258.2831,10001.16879,192.547338,10001.07615,198.508706,10000.98484,,,,
17.514138,225.999561,10001.21145,,,,,,,,,,,,,,,,,,,,,193.528039,10003.58568,232.925775,10000.86168,259.726488,10000.98168,253.960734,10001.23228,202.57914,10001.1409,242.627857,10000.88942,263.286159,10001.2555,197.956205,10001.22584,194.817951,10001.04402,257.467555,10000.79075,205.088989,10000.83498,212.965019,10001.10094,231.093396,10000.91643,254.307847,10001.0219,194.988449,10001.22812,207.136762,10001.30036,262.305435,10001.37355,195.25804,10000.88722,261.969945,10001.32872,220.098748,10001.25046,200.082104,10001.0408,258.452244,10001.17811,192.637114,10001.11261,198.481586,10000.83676,,,,
17.819431,226.103633,10001.13687,,,,,,,,,,,,,,,,,,,,,193.84971,10003.45039,233.046879,10000.88785,259.968007,10001.13442,254.394162,10001.21828,202.827812,10001.07076,242.703432,10000.93522,263.437275,10001.2345,198.246945,10001.21168,195.240372,10001.11044,257.662201,10000.79287,205.46906,10000.99736,213.365437,10001.09496,231.696139,10000.92281,254.268493,10000.87089,195.092399,10001.24511,207.183051,10001.36103,262.454504,10001.33542,195.877568,10000.76626,262.613929,10001.37648,220.116016,10001.18873,200.439553,10001.1983,259.080804,10001.2639,192.911776,10001.15405,198.828229,10000.80409,,,,
18.124723,226.33658,10001.16977,,,,,,,,,,,,,,,,,,,,,193.848304,10003.48231,233.093164,10000.8515,260.330464,10001.03476,254.661336,10001.26745,203.254935,10000.96515,242.995595,10000.89834,263.264899,10001.28869,198.517404,10001.31158,195.25748,10001.12378,258.029657,10000.85817,205.383634,10000.94768,213.466988,10001.05412,231.489048,10000.80593,254.335567,10000.98246,195.456181,10001.3054,207.33672,10001.3386,262.45445,10001.36207,195.982854,10000.77295,262.841845,10001.40741,220.094875,10001.25758,200.345251,10001.1016,259.046402,10001.22168,193.074606,10001.17793,198.642136,10000.93845,,,,
18.430016,226.317438,10001.22403,,,,,,,,,,,,,,,,,,,,,193.940693,10003.39709,233.632816,10000.92852,260.413735,10000.99628,254.53728,10001.28157,203.084969,10001.10396,243.348295,10000.82354,263.778509,10001.34487,198.41375,10001.28036,195.532978,10001.10902,258.08838,10000.87186,205.58614,10000.91612,213.77118,10000.97281,231.794815,10000.88877,254.902174,10000.77034,195.519634,10001.29934,207.502865,10001.3886,263.056085,10001.343,196.067607,10000.77293,262.632202,10001.36024,220.176284,10001.25133,200.672412,10001.0727,259.432275,10001.26198,193.299094,10001.20388,199.274784,10000.71358,,,,
18.735309,226.771222,10001.25443,,,,,,,,,,,,,,,,,,,,,193.967287,10003.37231,233.794618,10000.96451,260.434999,10001.04878,254.79639,10001.27559,203.536691,10001.15522,243.207433,10000.89282,264.07856,10001.30261,198.779481,10001.33109,195.821352,10001.13289,258.215634,10000.8762,205.9995,10001.03085,213.47424,10001.10174,231.985659,10000.95614,255.091442,10000.9416,195.845568,10001.37305,207.894788,10001.33262,262.781453,10001.34051,196.836216,10000.76355,262.98644,10001.34363,220.254976,10001.14695,200.954787,10001.0747,259.047086,10001.25856,193.484294,10001.2262,199.233515,10000.83352,,,,
19.040602,226.737229,10001.25895,,,,,,,,,,,,,,,,,,,,,194.036553,10003.33456,233.769669,10000.93727,260.86168,10000.92485,255.115908,10001.32599,203.712927,10000.99748,243.49699,10000.81943,264.301202,10001.28583,198.895477,10001.31893,196.394025,10001.1854,258.680564,10000.91547,206.1874,10001.02452,213.878392,10000.97893,232.175656,10000.92071,255.381054,10000.78361,196.184551,10001.38516,207.92331,10001.21044,263.137052,10001.2139,196.292169,10000.90115,262.833481,10001.41178,220.390538,10001.21699,201.054208,10000.9935,259.538806,10001.28813,193.117918,10001.16503,199.203181,10000.80713,,,,
19.345895,225.464957,9755.786825,,,,,,,,,,,,,,,,,,,,,192.758993,9758.143517,232.605478,9755.816808,259.885311,9755.821592,253.907186,9755.785018,202.610635,9755.748028,242.055633,9755.798736,262.971879,9755.806899,197.364893,9755.829689,194.547853,9755.811608,257.805267,9755.812752,205.051508,9755.790151,212.850082,9755.798159,231.162065,9755.813009,254.237815,9755.81574,194.590775,9755.797227,206.771391,9755.858996,262.532672,9755.867245,194.987487,9755.776149,261.823178,9755.838587,219.618708,9755.851399,200.014607,9755.8404,258.573455,9755.839804,192.245943,9755.854037,198.372457,9755.780086,,,,
19.651187,223.840049,9450.617793,,,,,,,,,,,,,,,,,,,,,191.098087,9452.788382,230.937258,9450.707294,257.974253,9450.658667,252.207447,9450.661471,200.803309,9450.643842,240.753059,9450.697864,261.897549,9450.681432,195.850148,9450.654578,193.246379,9450.66344,255.764756,9450.643468,202.980742,9450.661803,210.816365,9450.60044,229.50783,9450.706971,252.347051,9450.644093,192.898792,9450.649604,204.864667,9450.636798,260.697202,9450.676321,193.879221,9450.716895,260.609442,9450.711158,217.788365,9450.720698,198.033653,9450.67097,256.978915,9450.674812,189.962451,9450.614261,196.025637,9450.651765,,,,
19.95648,222.118417,9145.647838,,,,,,,,,,,,,,,,,,,,,188.988709,9147.576275,229.186989,9145.620827,256.377539,9145.676012,250.610689,9145.638352,199.037786,9145.559951,238.809932,9145.618728,260.188289,9145.641428,193.842318,9145.546015,191.061368,9145.527973,254.527855,9145.594152,201.381695,9145.523682,208.970315,9145.540866,227.702504,9145.60527,250.812138,9145.687794,191.020991,9145.549579,202.967659,9145.524554,258.784825,9145.616465,191.918147,9145.60607,259.009488,9145.656061,216.131833,9145.668069,196.061415,9145.56867,255.202529,9145.599565,188.613198,9145.557428,194.587533,9145.57939,,,,
20.261773,220.255625,8840.378862,,,,,,,,,,,,,,,,,,,,,187.099761,8842.083467,227.407663,8840.456176,255.186709,8840.42889,248.568323,8840.42251,197.218361,8840.391038,236.847938,8840.413418,258.464616,8840.404447,192.230449,8840.439822,189.131482,8840.405595,252.345065,8840.364791,199.224573,8840.410011,207.088387,8840.432693,226.121167,8840.412056,248.967759,8840.392295,189.424574,8840.433394,201.461627,8840.470018,257.273756,8840.400011,190.092109,8840.413089,257.041791,8840.454776,214.372863,8840.43132,194.167393,8840.40629,253.661289,8840.403108,186.625716,8840.454409,192.236989,8840.380628,,,,
20.567066,218.642505,8535.294235,,,,,,,,,,,,,,,,,,,,,185.206454,8536.830175,225.631046,8535.351178,253.186829,8535.378704,247.177715,8535.324244,195.105183,8535.317499,235.186154,8535.296836,256.827016,8535.300764,189.951871,8535.346971,187.491602,8535.391117,250.948285,8535.321938,197.414751,8535.33988,205.311995,8535.313663,224.400757,8535.373445,247.286482,8535.354832,187.565093,8535.374326,199.509202,8535.346904,255.93189,8535.3385,188.23282,8535.338329,256.125314,8535.334935,211.863413,8535.299608,192.786649,8535.32852,252.032484,8535.276484,184.870388,8535.35872,190.489716,8535.28083,,,,
20.872359,216.711989,8230.285954,,,,,,,,,,,,,,,,,,,,,183.201488,8231.561441,223.765621,8230.259177,251.560758,8230.286747,245.41276,8230.268847,193.129941,8230.211016,233.416741,8230.339363,255.198925,8230.294849,188.354361,8230.263214,185.373381,8230.211742,249.176843,8230.288156,195.207923,8230.183977,203.191032,8230.252081,222.856665,8230.268611,245.542919,8230.302306,185.568922,8230.226902,197.689055,8230.240102,253.94391,8230.298406,186.114608,8230.215572,253.67819,8230.307702,210.669726,8230.293191,190.467651,8230.25679,250.15741,8230.311262,182.802314,8230.277332,188.458894,8230.237005,,,,
21.177651,214.574804,7925.087973,,,,,,,,,,,,,,,,,,,,,180.841799,7926.114293,222.248668,7925.152936,249.806268,7925.12579,243.24859,7925.119605,191.178349,7925.073675,231.411233,7925.15171,253.569782,7925.146528,186.619091,7925.118077,183.495284,7925.116844,247.758218,7925.113956,193.59012,7925.158152,201.322904,7925.146359,220.925289,7925.145045,243.677581,7925.102874,183.802632,7925.133073,195.521475,7925.151216,252.39165,7925.079591,184.58341,7925.127733,252.395688,7925.145214,208.250415,7925.096577,188.847755,7925.11834,248.0752,7925.115018,180.483192,7925.131264,186.611221,7925.087732,,,,
21.482944,212.754887,7620.030138,,,,,,,,,,,,,,,,,,,,,178.996768,7620.848845,219.786549,7620.048507,248.183401,7620.085529,241.509033,7620.0315,189.286431,7620.079975,229.367655,7620.052646,251.863514,7620.0323,184.519205,7620.059027,181.587367,7620.067893,245.695928,7620.052544,191.514824,7620.035248,199.536503,7620.020057,219.280812,7620.061258,242.273106,7620.097634,181.668546,7620.093803,193.754356,7620.000312,250.922049,7619.999204,182.283139,7620.030557,250.507211,7620.03429,206.494991,7620.052921,186.450919,7620.05975,246.437069,7620.045865,178.807252,7620.074698,184.651671,7620.057396,,,,
21.788237,210.815507,7314.986183,,,,,,,,,,,,,,,,,,,,,176.736756,7315.631014,217.924952,7315.008925,246.1019,7314.989368,239.49741,7315.047752,187.158867,7314.951316,227.605787,7315.035885,249.93536,7315.015494,182.559937,7314.974073,179.7397,7314.952314,243.947299,7314.997692,189.568439,7314.967572,197.368101,7315.001881,217.069826,7314.985105,240.029608,7315.027096,179.634173,7314.966052,191.682361,7314.97779,249.001245,7315.077053,180.262091,7314.976522,248.988611,7315.024865,204.573078,7315.007717,184.515967,7314.98597,244.665656,7315.014656,176.381533,7314.963432,182.518285,7314.997536,,,,
22.09353,208.922469,7009.906252,,,,,,,,,,,,,,,,,,,,,174.693665,7010.310232,216.171151,7009.963994,244.409715,7009.966911,237.677513,7009.938331,185.145551,7009.948126,225.438287,7009.961191,248.215077,7009.957855,180.645467,7009.942853,177.675536,7009.953665,241.890837,7009.964498,187.368154,7009.976423,195.360121,7009.981836,215.478741,7009.971028,238.474703,7009.940103,177.882974,7009.971577,189.609319,7009.934075,247.036286,7009.931886,178.346801,7009.959933,247.264204,7009.985423,202.955768,7009.951605,182.668618,7009.95993,242.869256,7009.992625,174.76642,7009.93745,180.239528,7009.934745,,,,
22.398823,206.916784,6704.867031,,,,,,,,,,,,,,,,,,,,,172.586343,6705.023097,213.955257,6704.834483,242.530852,6704.858466,235.928224,6704.860977,183.039308,6704.878576,223.597721,6704.865139,246.561878,6704.855192,178.590733,6704.877751,175.590503,6704.880582,240.075131,6704.849942,185.36801,6704.862125,193.022453,6704.84124,213.378368,6704.868451,236.525592,6704.874315,175.745779,6704.865057,187.676134,6704.877841,245.127964,6704.820827,176.664291,6704.882394,245.435436,6704.878054,200.380851,6704.882938,180.622301,6704.87578,240.899246,6704.837836,172.377629,6704.875137,178.33041,6704.875469,,,,
22.704115,204.433044,6399.848569,,,,,,,,,,,,,,,,,,,,,170.220754,6399.794888,211.77289,6399.864632,240.534604,6399.845856,233.991542,6399.868559,180.824417,6399.842821,221.424636,6399.87212,244.43799,6399.884693,176.455048,6399.85845,173.496527,6399.860245,238.029584,6399.847337,183.01786,6399.875853,190.909673,6399.866879,211.34967,6399.840408,234.405296,6399.869657,173.598679,6399.846436,185.718441,6399.869349,243.362803,6399.882868,174.051056,6399.865616,243.245398,6399.838423,198.270092,6399.847775,178.059029,6399.88845,239.607862,6399.872005,170.281737,6399.869527,176.072686,6399.864693,,,,
23.009408,202.574033,6094.85076,,,,,,,,,,,,,,,,,,,,,168.240534,6094.549085,209.632692,6094.844101,238.766592,6094.822391,231.743117,6094.856895,178.767877,6094.847291,219.653576,6094.844624,242.677635,6094.830664,174.524405,6094.853862,171.355735,6094.866607,236.39346,6094.870439,181.05438,6094.850187,188.919955,6094.837283,209.492055,6094.891461,232.598329,6094.85027,171.883605,6094.849244,183.628095,6094.842552,241.91973,6094.82736,171.781916,6094.840842,241.866137,6094.858564,196.27125,6094.858905,176.319244,6094.81166,237.409909,6094.856276,168.233189,6094.812005,173.856616,6094.810067,,,,
23.314701,200.564171,5789.783963,,,,,,,,,,,,,,,,,,,,,165.88784,5789.305886,207.81867,5789.77447,236.575235,5789.774016,229.959876,5789.797602,176.598187,5789.800339,217.519554,5789.773652,240.981896,5789.789786,172.246915,5789.824283,169.397913,5789.794807,234.103808,5789.777432,178.963716,5789.848877,186.78856,5789.823288,207.344107,5789.757101,230.566678,5789.793981,169.707125,5789.823773,181.291646,5789.824006,240.013351,5789.771229,170.208457,5789.828386,239.580913,5789.773737,194.407902,5789.791166,174.085189,5789.82584,235.383803,5789.802071,165.881801,5789.824356,171.610533,5789.8535,,,,
23.619994,198.320302,5484.845531,,,,,,,,,,,,,,,,,,,,,163.293516,5484.117729,205.414738,5484.865261,234.556775,5484.810223,227.722171,5484.848493,174.191929,5484.896427,215.325445,5484.814712,239.039683,5484.863555,170.02708,5484.87981,166.830979,5484.900282,232.435808,5484.873852,176.527735,5484.894705,184.464462,5484.912092,205.416619,5484.858685,228.618343,5484.852509,167.279307,5484.904181,179.315232,5484.876238,237.78505,5484.849914,167.556627,5484.893106,237.462367,5484.830646,192.076736,5484.866043,172.048006,5484.86592,233.458742,5484.839588,163.576902,5484.872052,169.743891,5484.871677,,,,
23.925287,195.965693,5179.890225,,,,,,,,,,,,,,,,,,,,,161.058289,5178.917916,203.609178,5179.797742,232.619228,5179.82882,225.696866,5179.880984,172.07197,5179.846696,212.960096,5179.818009,236.961799,5179.871873,167.771194,5179.853839,164.889008,5179.869798,229.987889,5179.861551,174.583104,5179.864533,182.128206,5179.900104,203.385896,5179.875853,226.335754,5179.834442,165.21893,5179.847103,177.049358,5179.858907,236.113534,5179.84737,165.757924,5179.837139,235.837721,5179.851611,190.070418,5179.833364,169.291586,5179.84473,231.549837,5179.862094,161.710247,5179.81961,167.128142,5179.841521,,,,
24.230579,193.795923,4874.975166,,,,,,,,,,,,,,,,,,,,,158.557605,4873.810153,201.224877,4874.925199,230.573482,4874.914581,223.727451,4874.930086,169.61077,4874.970646,210.966773,4874.921007,235.072221,4874.94663,165.875845,4874.984245,162.434899,4874.972489,228.284587,4874.944553,172.226918,4874.974868,179.929273,4874.97745,201.31721,4874.942124,224.372056,4874.945251,162.827986,4874.982533,174.709065,4875.01119,233.69619,4874.914488,163.158143,4874.975903,233.87729,4874.89448,187.359828,4874.986578,167.706342,4874.96565,228.99339,4874.939956,159.484819,4874.990245,165.142383,4875.016345,,,,
24.535872,191.558726,4570.012016,,,,,,,,,,,,,,,,,,,,,156.562976,4568.611548,198.720088,4570.010778,228.36984,4569.96083,221.466307,4569.995104,167.328299,4570.028892,208.516004,4569.994444,232.917423,4569.999662,163.498446,4570.018138,160.192531,4570.026168,225.95684,4570.01613,169.757145,4570.064813,177.584489,4570.072254,199.216261,4570.008392,222.216599,4569.96608,160.5502,4570.041122,172.4823,4570.059058,231.589499,4570.013273,160.773411,4570.05832,231.884424,4569.949536,185.414191,4570.008483,164.897423,4570.0282,226.742955,4569.999406,157.104197,4570.032794,162.482339,4570.065375,,,,
24.841165,189.426885,4265.147158,,,,,,,,,,,,,,,,,,,,,154.008139,4263.584417,196.869775,4265.100432,226.289782,4265.120013,219.040332,4265.180477,164.816577,4265.148011,206.521753,4265.121774,230.841166,4265.132223,161.479776,4265.101716,157.766615,4265.167363,223.975634,4265.137226,167.559204,4265.159523,175.105691,4265.151993,196.92793,4265.156539,220.167634,4265.134545,158.318231,4265.135712,169.878723,4265.131042,229.934073,4265.13924,158.922225,4265.098261,229.815478,4265.122021,183.214747,4265.126428,162.931183,4265.09684,224.720575,4265.137997,154.781307,4265.136804,160.158647,4265.174628,,,,
25.146458,186.693394,3960.357207,,,,,,,,,,,,,,,,,,,,,151.51984,3958.522263,194.264319,3960.347584,224.2599,3960.266909,216.90689,3960.329392,162.335668,3960.313955,204.012626,3960.318273,228.720388,3960.371799,158.693224,3960.324036,155.392062,3960.332761,221.680739,3960.335626,165.026333,3960.318915,172.678575,3960.373678,194.673488,3960.312363,217.594528,3960.321659,156.181407,3960.325644,167.650314,3960.373634,227.648869,3960.346818,156.558856,3960.295473,227.821495,3960.279384,181.319873,3960.277696,160.304144,3960.32533,222.722583,3960.354638,152.007689,3960.329098,157.686911,3960.391356,,,,
25.451751,184.268177,3655.567771,,,,,,,,,,,,,,,,,,,,,148.849147,3653.526018,191.637564,3655.549298,221.953655,3655.499892,214.586539,3655.544742,159.818957,3655.636665,201.267281,3655.506122,226.604964,3655.545698,156.513297,3655.609712,153.073737,3655.623337,219.466453,3655.554495,162.613905,3655.61885,170.358668,3655.625876,192.430218,3655.549966,215.385466,3655.52228,153.734389,3655.613057,165.168772,3655.642864,225.669392,3655.541692,153.493382,3655.627118,225.389132,3655.513414,178.757017,3655.527344,158.220585,3655.57491,220.498658,3655.553746,149.678307,3655.604489,155.529234,3655.622972,,,,
25.757044,181.776729,3350.897311,,,,,,,,,,,,,,,,,,,,,146.237256,3348.626174,189.436723,3350.80378,219.439398,3350.816612,212.392081,3350.877778,157.240384,3350.848934,198.855735,3350.821257,224.354303,3350.863071,153.860528,3350.849441,150.316594,3350.868267,216.745671,3350.882986,159.847728,3350.866739,167.585716,3350.892803,189.984317,3350.886488,213.049956,3350.84986,151.285233,3350.85079,163.035535,3350.873424,223.141031,3350.874636,151.04129,3350.869413,222.637528,3350.868801,176.205364,3350.828445,155.16923,3350.84596,218.243544,3350.861909,146.802561,3350.882776,152.687522,3350.908587,,,,
26.062336,179.347209,3046.207688,,,,,,,,,,,,,,,,,,,,,143.420757,3043.725871,186.864243,3046.167278,217.320377,3046.132282,210.127287,3046.184129,154.874929,3046.171517,196.449297,3046.13199,222.233868,3046.182292,151.460263,3046.159404,147.986932,3046.158461,214.541534,3046.209344,157.065093,3046.207433,165.051997,3046.229498,187.979585,3046.18129,210.714149,3046.192823,148.622119,3046.194157,160.404464,3046.232845,221.102516,3046.160968,149.196816,3046.162178,220.7257,3046.10001,173.988606,3046.109578,153.260646,3046.14621,216.212817,3046.188837,144.649088,3046.154739,150.487502,3046.196353,,,,
26.367629,176.700548,2741.681306,,,,,,,,,,,,,,,,,,,,,140.918947,2738.955098,184.241756,2741.580533,214.805291,2741.586424,207.545185,2741.663234,151.879042,2741.693474,193.849816,2741.602049,219.765429,2741.645499,149.25237,2741.634305,145.305103,2741.690584,212.111743,2741.644882,154.94463,2741.661469,162.522623,2741.69644,185.393884,2741.638751,208.080819,2741.602341,146.249384,2741.687638,157.734737,2741.695488,218.884549,2741.604731,146.098336,2741.690394,218.706789,2741.56272,171.312535,2741.590009,150.447576,2741.63022,213.39778,2741.649394,141.943533,2741.658175,147.596155,2741.728275,,,,
26.672922,173.973372,2437.269022,,,,,,,,,,,,,,,,,,,,,138.002166,2434.344784,181.494859,2437.194166,212.064714,2437.154123,204.660399,2437.26275,149.254009,2437.274221,191.183968,2437.184705,217.757301,2437.219264,146.50964,2437.201643,142.941739,2437.225753,209.775056,2437.22197,151.933862,2437.236878,159.534609,2437.300048,182.951416,2437.219476,205.62894,2437.206085,143.514386,2437.245351,155.262561,2437.256769,216.415639,2437.17674,143.885441,2437.191306,216.241904,2437.135541,168.680853,2437.181052,147.983557,2437.19603,210.995483,2437.221494,139.142047,2437.259003,145.224791,2437.286093,,,,
26.978215,171.11826,2132.974287,,,,,,,,,,,,,,,,,,,,,134.989119,2129.821388,178.74249,2132.930111,209.637572,2132.852226,201.935658,2132.982646,146.398939,2132.985582,188.385556,2132.919722,214.942643,2132.950542,143.940399,2132.925199,140.132292,2132.945408,206.806235,2132.972559,149.104635,2132.999931,156.760725,2133.039026,179.941908,2132.987331,203.085959,2132.909606,140.943828,2132.966221,152.013364,2133.031742,213.937238,2132.877285,140.976406,2132.949692,213.433239,2132.845278,166.044812,2132.909361,145.04861,2132.93293,208.080553,2132.976059,136.274723,2132.956994,142.078381,2133.027922,,,,
27.283508,167.960374,1828.923378,,,,,,,,,,,,,,,,,,,,,132.082827,1825.535357,175.867883,1828.824529,206.997585,1828.793441,199.307931,1828.919433,143.418788,1828.945484,185.633374,1828.841405,212.32924,1828.853474,141.124172,1828.885861,137.104503,1828.908746,204.237934,1828.895661,146.058762,1828.931759,153.569873,1828.96479,177.260094,1828.897617,200.153272,1828.842903,138.097369,1828.911605,149.337149,1828.947578,210.924759,1828.833835,138.005414,1828.923574,210.340261,1828.824385,163.005774,1828.853,142.180317,1828.8584,205.177518,1828.891402,133.090568,1828.937689,139.084892,1829.001521,,,,
27.5888,164.816175,1525.202821,,,,,,,,,,,,,,,,,,,,,128.904215,1521.588082,172.845281,1525.108192,203.926019,1525.074916,196.694675,1525.165266,140.425529,1525.237631,182.546351,1525.131559,209.414273,1525.169381,138.070584,1525.197146,134.185692,1525.211663,201.420206,1525.139654,142.700161,1525.254496,150.571623,1525.275766,174.436077,1525.195663,197.059684,1525.149452,134.87302,1525.254776,146.681243,1525.228595,208.154432,1525.10217,135.140312,1525.191211,207.247546,1525.132422,159.978029,1525.172004,138.880594,1525.21181,202.528315,1525.160489,129.971265,1525.231145,136.199992,1525.310884,,,,
27.894093,161.255286,1221.996721,,,,,,,,,,,,,,,,,,,,,125.35333,1218.134636,169.379728,1221.915841,200.91566,1221.84405,193.316791,1221.964787,136.996403,1222.060464,179.099371,1221.906998,206.452493,1221.917163,134.977227,1222.000081,130.986694,1222.004315,198.467042,1221.921942,139.520011,1222.012395,146.988007,1222.088987,171.444446,1221.958764,194.087388,1221.893798,131.835113,1222.015193,143.06648,1222.052264,205.103253,1221.90582,131.807952,1221.989268,204.523797,1221.854205,156.868839,1221.920364,135.347139,1222.02592,199.333639,1221.945538,126.109272,1222.051377,132.902526,1222.090111,,,,
28.199386,157.335754,919.642568,,,,,,,,,,,,,,,,,,,,,121.651879,915.535298,165.876613,919.554476,197.668197,919.462137,189.59076,919.620942,133.571116,919.717099,175.641149,919.56416,203.140614,919.558372,131.831216,919.609657,127.559123,919.637009,194.93461,919.558649,135.773773,919.706879,143.652968,919.724912,168.228888,919.592636,190.544581,919.550563,128.505076,919.671458,139.506351,919.716605,202.07544,919.475168,127.688485,919.710656,201.004205,919.509321,153.492125,919.582721,131.814563,919.662989,195.801473,919.5736,122.29078,919.710751,129.13899,919.78106,,,,
28.504679,152.820879,618.886707,,,,,,,,,,,,,,,,,,,,,117.288233,614.538575,162.099631,618.771833,194.12797,618.664613,185.904485,618.81322,129.779261,619.045584,171.9145,618.783034,199.941656,618.740604,127.99049,618.945144,123.193056,619.028285,191.544955,618.754817,131.624322,619.054498,139.845851,619.009148,164.379046,618.882333,187.145775,618.727186,124.698421,618.97761,135.511205,619.030137,198.325847,618.687973,124.283605,618.95447,197.526772,618.692972,149.873971,618.834984,127.863907,618.969848,192.772587,618.709352,118.02557,619.01078,124.961852,619.111224,,,,
28.809972,147.998647,322.070302,,,,,,,,,,,,,,,,,,,,,111.940738,317.507414,157.228257,322.06915,189.86756,321.840886,181.438025,322.024077,125.082245,322.469741,167.399973,322.02973,195.630497,321.907766,123.394814,322.391373,118.369883,322.482361,187.131696,321.969923,126.984045,322.422405,135.117925,322.428736,160.450912,322.121405,182.901716,321.928515,119.465284,322.461274,130.72209,322.38961,194.347513,321.74314,119.029449,322.411366,193.250681,321.853348,145.023105,322.173909,123.015815,322.380371,188.598315,321.86274,111.93368,322.535294,120.05373,322.520514,,,,
29.10025,141.56231,54.391889,,,,,,,,,,,,,,,,,,,,,104.232594,49.553962,148.004377,55.081877,184.96954,53.925968,175.800049,54.342895,118.665815,55.960821,156.342062,55.034628,190.837003,53.894422,117.714899,55.854259,111.887189,56.080477,182.024545,54.150062,120.241435,55.860168,129.248798,55.6398,152.735033,55.105182,177.589779,54.175032,112.5744,55.996368,119.144945,55.939362,189.495484,53.466283,112.0214,55.801653,188.582532,53.834026,134.514183,55.429755,116.487136,55.863493,183.305488,53.991771,101.846039,56.448669,113.128518,55.958848,,,,