File: data/100kN_peak_compression_25C.csv
Average,,,,E0,E1,Analog,,,,,,,,,,,
Index [1],exx [1] - engr.,eyy [1] - engr.,exy [1] - engr.,ΔL/L0 [0] Extensometer x-strain,ΔL/L0 [1] Extensometer y-strain,Time_0,Disp_mm,Load_N,Area,,Strain,Stress,,Possion,,,
0,0,0,-1.88E-17,,0,0,-0.0002,-6.4415,0.00005413,,0,0.119000554,,,,0.209876301,0.25421138
1,-0.000132461,4.54E-06,-4.45E-05,-3.27E-05,-3.42E-05,1.0023,-0.0001,25.7661,,,-4.54E-06,-0.476004064,,2.92E+01,,0.18759576,
2,-3.82E-05,-4.20E-06,-1.53E-05,-3.94E-05,-2.13E-05,2.0068,0.0001,-12.8831,,,4.20E-06,0.238002956,,-9.09E+00,,0.360120584,
3,-4.43E-05,4.68E-06,-8.16E-05,-3.41E-07,7.46E-05,3.0031,-0.0001,-25.7662,,,-4.68E-06,0.476005912,,9.46E+00,,0.230343635,
4,-2.11E-05,1.85E-05,-2.87E-05,5.90E-06,4.19E-05,4.0011,-0.0001,6.4415,,,-1.85E-05,-0.119000554,,1.14E+00,,0.190155215,
5,-7.29E-06,8.84E-06,6.50E-05,8.68E-06,3.27E-05,5.0083,-0.0013,-12.8831,,,-8.84E-06,0.238002956,,8.25E-01,,0.299936189,
6,-3.29E-05,-0.000157243,-7.15E-05,9.60E-06,7.17E-06,6.0063,-0.0035,-3.2208,,,0.000157243,0.059501201,,-2.09E-01,,0.216711001,
7,0.000134167,-0.000251,6.72E-05,-4.70E-06,-2.78E-05,7.0053,-0.0055,-16.1039,,,0.000251,0.297504157,,5.35E-01,,0.309738248,
8,-1.60E-05,-0.000350044,3.56E-05,-0.000103474,-4.17E-06,8.0021,-0.0079,-32.2077,,,0.000350044,0.595006466,,-4.57E-02,,0.330700867,
9,-5.43E-05,-0.000321826,-5.96E-05,-0.000119374,-6.36E-05,9.003,-0.0097,-80.5192,,,0.000321826,1.487515241,,-1.69E-01,,0.196935094,
10,5.81E-05,-0.000391957,-2.65E-05,-0.000183193,1.77E-05,10.0001,-0.0119,-161.038,,,0.000391957,2.975023093,,1.48E-01,,0.311161255,
11,1.34E-05,-0.000381091,-8.93E-05,-0.00017695,3.43E-05,11.0033,-0.014,-228.674,,,0.000381091,4.22453353,,3.51E-02,,0.221933375,
12,6.01E-05,-0.000410555,-0.000107165,-0.000183261,5.02E-05,12.0031,-0.0161,-338.181,,,0.000410555,6.247570663,,1.46E-01,,0.207043028,
13,7.03E-05,-0.000431236,-9.57E-05,-0.000218157,5.21E-05,13.0051,-0.0183,-457.349,,,0.000431236,8.449085535,,1.63E-01,,0.244041407,
14,7.69E-05,-0.000465482,-7.22E-05,-0.000279145,9.24E-06,14.0046,-0.0204,-611.946,,,0.000465482,11.30511731,,1.65E-01,,0.319730432,
15,0.00013103,-0.000464257,-9.21E-05,-0.000283752,8.58E-05,15.0063,-0.0225,-743.997,,,0.000464257,13.74463329,,2.82E-01,,0.152124198,
16,0.000106958,-0.000509624,-0.000126056,-0.000266182,5.77E-05,16.006,-0.0246,-908.257,,,0.000509624,16.77917975,,2.10E-01,,0.267733658,
17,0.000108971,-0.000580882,-0.000110426,-0.0003095,8.81E-05,17.0049,-0.0266,-1072.52,,,0.000580882,19.81378164,,1.88E-01,,0.230570545,
18,0.000222552,-0.000617993,-0.000147961,-0.000385964,5.75E-05,18.0059,-0.0287,-1249.66,,,0.000617993,23.08627379,,3.60E-01,,0.187710756,
19,0.00015375,-0.000667481,-7.93E-05,-0.000430462,0.000143057,19.0053,-0.0309,-1426.8,,,0.000667481,26.35876593,,2.30E-01,,0.227113892,
20,0.000127203,-0.000668943,-0.000180396,-0.000455697,0.000118611,20.0051,-0.0329,-1632.93,,,0.000668943,30.16682062,,1.90E-01,,0.226000355,
21,0.000204938,-0.000683272,-0.000164359,-0.000459987,0.000173883,21.006,-0.0352,-1803.63,,,0.000683272,33.32033992,,3.00E-01,,0.277301336,
22,0.000165868,-0.000765388,-0.000122024,-0.000521257,0.000111055,22.0056,-0.0372,-2022.64,,,0.000765388,37.36634029,,2.17E-01,,0.29762222,
23,0.000236334,-0.000763012,-0.000154788,-0.000537128,0.000149837,23.0062,-0.0394,-2219.11,,,0.000763012,40.99593571,,3.10E-01,,0.297473349,
24,0.000273274,-0.000826348,-0.000171005,-0.000577321,0.000163767,24.0044,-0.0413,-2422.02,,,0.000826348,44.74450397,,3.31E-01,,0.182067732,
25,0.000161511,-0.000820123,-0.00025474,-0.00053836,0.000233531,25.0045,-0.0434,-2624.93,,,0.000820123,48.49307223,,1.97E-01,,0.243454436,
26,0.000293033,-0.00094174,-0.000153251,-0.000679312,0.000272554,26.0021,-0.0457,-2856.82,,,0.00094174,52.77701829,,3.11E-01,,0.195977819,
27,0.000207794,-0.00093629,-0.000268449,-0.000671271,0.000258371,27.0017,-0.0477,-3046.85,,,0.00093629,56.28764086,,2.22E-01,,0.241192847,
28,0.000210952,-0.00101888,-0.00020188,-0.000718701,0.000238351,28.0033,-0.0499,-3265.86,,,0.00101888,60.33364123,,2.07E-01,,0.233644278,
29,0.000232918,-0.00095442,-0.000171785,-0.000709368,0.000243581,29.0056,-0.052,-3507.42,,,0.00095442,64.7962313,,2.44E-01,,0.231033019,
30,0.000323564,-0.00101199,-0.000260712,-0.000788001,0.000357406,30.0043,-0.0542,-3732.87,,,0.00101199,68.96120451,,3.20E-01,,0.199678231,
31,0.000161778,-0.00106346,-0.000242684,-0.000877995,0.000257475,31.0025,-0.0562,-3967.99,,,0.00106346,73.30482173,,1.52E-01,,0.203257472,
32,0.000281704,-0.00105218,-0.000230396,-0.000847293,0.000309571,32.0038,-0.0582,-4190.22,,,0.00105218,77.41030852,,2.68E-01,,0.281132797,
33,0.000260215,-0.00112857,-0.000288159,-0.000867561,0.000318077,33.0027,-0.0604,-4409.23,,,0.00112857,81.45630889,,2.31E-01,,0.286782261,
34,0.00022823,-0.00121586,-0.00033197,-0.000932244,0.000275783,34.0038,-0.0624,-4634.69,,,0.00121586,85.62146684,,1.88E-01,,0.202917844,
35,0.000280254,-0.00123398,-0.000291797,-0.000961091,0.000335698,35.0029,-0.0647,-4889.13,,,0.00123398,90.32200259,,2.27E-01,,0.250157234,
36,0.000280028,-0.00123906,-0.000304621,-0.000939847,0.000381503,36.0032,-0.0668,-5098.48,,,0.00123906,94.18954369,,2.26E-01,,0.233474716,
37,0.000348504,-0.00125677,-0.000144929,-0.000980156,0.000372321,37.0053,-0.0688,-5356.14,,,0.00125677,98.94956586,,2.77E-01,,0.26312099,
38,0.000382013,-0.00128355,-0.000296122,-0.00102466,0.000387061,38.0073,-0.071,-5571.93,,,0.00128355,102.9360798,,2.98E-01,,0.239730043,
39,0.000396529,-0.00133299,-0.000271783,-0.00105022,0.000443077,39.0043,-0.0732,-5842.47,,,0.00133299,107.9340477,,2.97E-01,,0.260124607,
40,0.000253431,-0.00139196,-0.000291416,-0.00113617,0.000406243,40.0065,-0.0752,-6090.47,,,0.00139196,112.5156106,,1.82E-01,,0.249448565,
41,0.000339877,-0.00139606,-0.000287344,-0.00109808,0.000442076,41.0043,-0.0773,-6306.26,,,0.00139606,116.5021245,,2.43E-01,,0.250702046,
42,0.000278849,-0.00142286,-0.00037007,-0.0011862,0.000276423,42.0006,-0.0795,-6592.91,,,0.00142286,121.7977092,,1.96E-01,,0.207275854,
43,0.0003604,-0.00149424,-0.000357157,-0.00122427,0.000413585,43.0037,-0.0817,-6834.47,,,0.00149424,126.2602993,,2.41E-01,,0.246721391,
44,0.000352908,-0.00151045,-0.00037007,-0.00121593,0.000484423,44.0058,-0.0836,-7105.02,,,0.00151045,131.2584519,,2.34E-01,,0.247337314,
45,0.00035909,-0.00155428,-0.00041132,-0.00126437,0.000495121,45.0059,-0.0857,-7311.14,,,0.00155428,135.0663218,,2.31E-01,,0.270450464,
46,0.000310282,-0.00155391,-0.000453444,-0.00131839,0.000414391,46.0037,-0.0878,-7578.47,,,0.00155391,140.004988,,2.00E-01,,0.27911431,
47,0.000314732,-0.00154844,-0.000363636,-0.00130907,0.000477457,47.0092,-0.09,-7839.35,,,0.00154844,144.8244966,,2.03E-01,,0.231296734,
48,0.000448404,-0.00159499,-0.00040742,-0.00130721,0.000513664,48.004,-0.0922,-8100.23,,,0.00159499,149.6440052,,2.81E-01,,0.257165903,
49,0.000475181,-0.00165694,-0.000232101,-0.00136627,0.000524167,49.0048,-0.0941,-8325.69,,,0.00165694,153.8091631,,2.87E-01,,0.248079448,
50,0.000345563,-0.00170297,-0.000371776,-0.00144853,0.000524905,50.0041,-0.0963,-8612.33,,,0.00170297,159.1045631,,2.03E-01,,0.232789225,
51,0.000431954,-0.00172673,-0.000464518,-0.00141418,0.000594365,51.0054,-0.0984,-8850.67,,,0.00172673,163.5076667,,2.50E-01,,0.227111006,
52,0.000423299,-0.00181304,-0.000484156,-0.00147535,0.000550943,52.005,-0.1006,-9111.55,,,0.00181304,168.3271753,,2.33E-01,,0.237186315,
53,0.000458933,-0.00174419,-0.000365815,-0.00147431,0.000529109,53.005,-0.1026,-9375.66,,,0.00174419,173.2063551,,2.63E-01,,0.251940768,
54,0.000446502,-0.00186252,-0.000454219,-0.00154627,0.00052714,54.0037,-0.1048,-9630.1,,,0.00186252,177.9068908,,2.40E-01,,0.250405581,
55,0.000476798,-0.00183296,-0.000340625,-0.00155546,0.00054754,55.0056,-0.1069,-9890.98,,,0.00183296,182.7263994,,2.60E-01,,0.230048791,
56,0.000462767,-0.00185516,-0.000496107,-0.00159362,0.000585241,56.0053,-0.109,-10158.3,,,0.00185516,187.6648808,,2.49E-01,,0.213666299,
57,0.000484409,-0.00193221,-0.000461629,-0.00170066,0.000614557,57.0052,-0.1112,-10438.5,,,0.00193221,192.841308,,2.51E-01,,0.259169925,
58,0.000403763,-0.00194795,-0.000404177,-0.00165015,0.000623991,58.0033,-0.1131,-10676.8,,,0.00194795,197.2436726,,2.07E-01,,0.268833462,
59,0.000486014,-0.00196989,-0.000290242,-0.0016426,0.000628103,59.0063,-0.1153,-10924.8,,,0.00196989,201.8252355,,2.47E-01,,0.220967002,
60,0.000486698,-0.00196775,-0.000397868,-0.00173854,0.000654558,60.0031,-0.1174,-11195.4,,,0.00196775,206.8243118,,2.47E-01,,0.266944035,
61,0.000552652,-0.00204345,-0.000362916,-0.00177902,0.000670099,61.0047,-0.1196,-11469.2,,,0.00204345,211.8825051,,2.70E-01,,0.269544798,
62,0.000589749,-0.00211293,-0.00032248,-0.00182856,0.000673833,62.0055,-0.1216,-11723.6,,,0.00211293,216.5823019,,2.79E-01,,0.24149411,
63,0.000504516,-0.00218125,-0.000566934,-0.00183411,0.000726568,63.0056,-0.1238,-11994.1,,,0.00218125,221.5795308,,2.31E-01,,0.292659929,
64,0.000554748,-0.00215716,-0.000481202,-0.001877,0.000702891,64.0015,-0.1258,-12267.9,,,0.00215716,226.637724,,2.57E-01,,0.259516196,
65,0.000540451,-0.00217854,-0.000339388,-0.00179519,0.000641423,65.0052,-0.128,-12509.5,,,0.00217854,231.101053,,2.48E-01,,0.231058166,
66,0.00051212,-0.00219993,-0.000490722,-0.00190099,0.000704902,66.0066,-0.13,-12789.7,,,0.00219993,236.2774801,,2.33E-01,,0.270979826,
67,0.000517561,-0.00227889,-0.000407243,-0.00194706,0.000719065,67.0038,-0.1322,-13044.1,,,0.00227889,240.9772769,,2.27E-01,,0.296830577,
68,0.000540633,-0.00227936,-0.00048604,-0.00200329,0.000725541,68.0054,-0.1345,-13298.6,,,0.00227936,245.6789211,,2.37E-01,,0.249276423,
69,0.000601952,-0.00238926,-0.000544883,-0.00207336,0.000754569,69.0054,-0.1364,-13565.9,,,0.00238926,250.6170331,,2.52E-01,,0.247226951,
70,0.000586838,-0.00234355,-0.000473193,-0.00200165,0.000713887,70.0038,-0.1385,-13842.9,,,0.00234355,255.7343432,,2.50E-01,,0.282601822,
71,0.000542692,-0.00235903,-0.000528658,-0.00208955,0.000705505,71.0046,-0.1407,-14126.3,,,0.00235903,260.9698873,,2.30E-01,,0.26637284,
72,0.000515205,-0.00241126,-0.000507924,-0.00215328,0.000755513,72.0041,-0.1428,-14380.7,,,0.00241126,265.6696841,,2.14E-01,,0.256122314,
73,0.000633629,-0.00244484,-0.000521461,-0.00212487,0.000788825,73.0024,-0.1448,-14673.8,,,0.00244484,271.0844264,,2.59E-01,,0.249021296,
74,0.000663938,-0.0024697,-0.000451113,-0.00214053,0.000850033,74.0036,-0.1471,-14947.6,,,0.0024697,276.1426196,,2.69E-01,,0.284086545,
75,0.000553582,-0.00250527,-0.000555724,-0.00215335,0.000825571,75.0052,-0.149,-15192.4,,,0.00250527,280.6650656,,2.21E-01,,0.23263451,
76,0.000662144,-0.00248046,-0.000570043,-0.00217618,0.00078973,76.0034,-0.1513,-15508,,,0.00248046,286.4954739,,2.67E-01,,0.2674259,
77,0.000686412,-0.00254656,-0.000536662,-0.00228249,0.000865032,77.0036,-0.1534,-15759.2,,,0.00254656,291.1361537,,2.70E-01,,0.259328318,
78,0.000620565,-0.00256969,-0.000647102,-0.00229286,0.000821301,78.0055,-0.1554,-16026.5,,,0.00256969,296.0742657,,2.41E-01,,0.257266523,
79,0.000755765,-0.0025824,-0.000424325,-0.00233878,0.000889069,79.0049,-0.1575,-16303.5,,,0.0025824,301.1915758,,2.93E-01,,0.272095494,
80,0.000686602,-0.0026457,-0.000516267,-0.00240687,0.000852911,80.0055,-0.1596,-16583.7,,,0.0026457,306.368003,,2.60E-01,,0.263466659,
81,0.000627755,-0.00271687,-0.000562795,-0.00242932,0.000842923,81.0042,-0.1616,-16847.8,,,0.00271687,311.246998,,2.31E-01,,0.259391553,
82,0.000701686,-0.00258944,-0.000545429,-0.00230653,0.00084414,82.005,-0.1638,-17140.9,,,0.00258944,316.6617403,,2.71E-01,,0.261457616,
83,0.000809549,-0.00272731,-0.000532275,-0.0024404,0.000896322,83.0042,-0.166,-17395.4,,,0.00272731,321.3633844,,2.97E-01,,0.248075356,
84,0.000701414,-0.0028138,-0.000579113,-0.00249161,0.000919728,84.0054,-0.168,-17678.8,,,0.0028138,326.5989285,,2.49E-01,,0.31467527,
85,0.000694238,-0.0028081,-0.000602299,-0.00252697,0.000937368,84.9989,-0.1702,-17946.1,,,0.0028081,331.5370405,,2.47E-01,,0.253912526,
86,0.000798986,-0.00282725,-0.000497524,-0.00256662,0.000943616,86.0026,-0.1723,-18252.1,,,0.00282725,337.1900979,,2.83E-01,,0.254871316,
87,0.000767255,-0.00288038,-0.000572243,-0.00260039,0.000925364,87.0033,-0.1744,-18503.3,,,0.00288038,341.8307778,,2.66E-01,,0.264205321,
88,0.000755589,-0.00295011,-0.000535643,-0.00262898,0.000994315,88.0052,-0.1765,-18806.1,,,0.00295011,347.4247183,,2.56E-01,,0.271667302,
89,0.000734822,-0.00295084,-0.00060354,-0.00262997,0.00098002,89.0058,-0.1788,-19095.9,,,0.00295084,352.7784962,,2.49E-01,,0.246373057,
90,0.000843345,-0.00296862,-0.000529651,-0.00269335,0.00105182,90.0062,-0.1808,-19363.3,,,0.00296862,357.7184556,,2.84E-01,,0.251634246,
91,0.000711729,-0.00305943,-0.000676157,-0.00278079,0.000978954,91.0031,-0.1828,-19627.4,,,0.00305943,362.5974506,,2.33E-01,,0.266056567,
92,0.000827274,-0.00309347,-0.000588243,-0.00277163,0.000981982,92.0045,-0.1849,-19888.3,,,0.00309347,367.4173287,,2.67E-01,,0.253799341,
93,0.000791094,-0.00305055,-0.000670439,-0.00275676,0.000981139,93.0044,-0.1871,-20184.6,,,0.00305055,372.8911879,,2.59E-01,,0.269978901,
94,0.000798846,-0.00310513,-0.000667366,-0.00277677,0.00105256,94.0028,-0.1893,-20455.1,,,0.00310513,377.8884168,,2.57E-01,,0.250364352,
95,0.000865748,-0.00318178,-0.000617964,-0.00285645,0.00108292,95.0046,-0.1912,-20741.8,,,0.00318178,383.1849252,,2.72E-01,,0.277871036,
96,0.000823249,-0.00312468,-0.000704732,-0.00281933,0.00108891,96.004,-0.1934,-20993,,,0.00312468,387.825605,,2.63E-01,,0.262579203,
97,0.000845728,-0.00326043,-0.000630224,-0.00292845,0.00107997,97.004,-0.1956,-21292.5,,,0.00326043,393.3585812,,2.59E-01,,0.246461486,
98,0.000850302,-0.00325216,-0.0006664,-0.00291985,0.00113278,98.0052,-0.1977,-21598.5,,,0.00325216,399.0116386,,2.61E-01,,0.258761655,
99,0.000827887,-0.00333724,-0.000712167,-0.00295111,0.00101113,99.0056,-0.1997,-21856.2,,,0.00333724,403.7723998,,2.48E-01,,0.250485618,
100,0.00103188,-0.00327919,-0.000474756,-0.00296639,0.00117606,100.007,-0.2018,-22165.3,,,0.00327919,409.4827268,,3.15E-01,,0.252701145,
101,0.00084545,-0.00332969,-0.000607176,-0.00305719,0.00108389,101.004,-0.2039,-22423,,,0.00332969,414.2434879,,2.54E-01,,0.265084269,
102,0.000872947,-0.00342505,-0.000575221,-0.00309463,0.0010647,102.005,-0.2059,-22703.2,,,0.00342505,419.419915,,2.55E-01,,0.269203755,
103,0.000893907,-0.00338338,-0.000686116,-0.00307317,0.00114986,103.005,-0.2082,-22986.6,,,0.00338338,424.6554591,,2.64E-01,,0.242187138,
104,0.000926141,-0.0034091,-0.000612009,-0.0031299,0.00114052,104.005,-0.2103,-23263.6,,,0.0034091,429.7727693,,2.72E-01,,0.247089105,
105,0.000869214,-0.00352804,-0.00075562,-0.00316255,0.00121617,105.002,-0.2123,-23556.7,,,0.00352804,435.1875115,,2.46E-01,,0.268950121,
106,0.000880818,-0.00350039,-0.000639562,-0.00322435,0.0011688,106.005,-0.2145,-23846.6,,,0.00350039,440.5431369,,2.52E-01,,0.261390935,
107,0.000925813,-0.00347976,-0.000703452,-0.00321558,0.00110576,107.006,-0.2168,-24110.7,,,0.00347976,445.4221319,,2.66E-01,,0.253685388,
108,0.000897904,-0.00353785,-0.0006504,-0.00324622,0.00120145,108.002,-0.2187,-24390.9,,,0.00353785,450.598559,,2.54E-01,,0.267809848,
109,0.000967383,-0.00358318,-0.000692333,-0.00327715,0.00117571,109.005,-0.2208,-24684,,,0.00358318,456.0133013,,2.70E-01,,0.253512252,
110,0.000896387,-0.00358033,-0.000726952,-0.00331154,0.00118338,110.003,-0.2229,-24967.4,,,0.00358033,461.2488454,,2.50E-01,,0.276916917,
111,0.00101471,-0.00365173,-0.000630375,-0.0033155,0.00123159,111.003,-0.2253,-25267,,,0.00365173,466.7836689,,2.78E-01,,0.26928311,
112,0.000965572,-0.00367726,-0.00049095,-0.00341069,0.00121142,112.006,-0.2273,-25524.6,,,0.00367726,471.5425827,,2.63E-01,,0.251607351,
113,0.000917793,-0.00372388,-0.000758249,-0.00343013,0.00118348,113.003,-0.2292,-25811.3,,,0.00372388,476.8390911,,2.46E-01,,0.272577617,
114,0.000979343,-0.00378473,-0.000794372,-0.00349366,0.00117556,114.005,-0.2317,-26085,,,0.00378473,481.8954369,,2.59E-01,,0.262900368,
115,0.000942124,-0.00376119,-0.000788206,-0.0034755,0.00125799,115.006,-0.2334,-26374.9,,,0.00376119,487.2510623,,2.50E-01,,0.260166,
116,0.000975621,-0.00386077,-0.000746177,-0.00353732,0.00133579,116.005,-0.2356,-26664.8,,,0.00386077,492.6066876,,2.53E-01,,0.24457381,
117,0.00102612,-0.00387092,-0.000770142,-0.00358184,0.00129182,117.003,-0.2377,-26957.9,,,0.00387092,498.0214299,,2.65E-01,,0.265500021,
118,0.00105018,-0.00390106,-0.000657658,-0.00357779,0.001357,118.005,-0.2399,-27234.8,,,0.00390106,503.1368927,,2.69E-01,,0.24200547,
119,0.000952476,-0.00393281,-0.000785222,-0.00364084,0.00130322,119.005,-0.2419,-27524.7,,,0.00393281,508.492518,,2.42E-01,,0.250875185,
120,0.000982535,-0.00397644,-0.000728872,-0.00372266,0.00134561,120.004,-0.2442,-27804.9,,,0.00397644,513.6689451,,2.47E-01,,0.269940917,
121,0.001077,-0.00400446,-0.000652396,-0.0036813,0.00130742,121.003,-0.2458,-28104.5,,,0.00400446,519.2037687,,2.69E-01,,0.25542495,
122,0.00105219,-0.00402535,-0.000698135,-0.00370541,0.00131726,122.003,-0.2482,-28371.8,,,0.00402535,524.1418807,,2.61E-01,,0.230387332,
123,0.00102083,-0.004024,-0.000742395,-0.00373796,0.00131686,123.004,-0.2504,-28681,,,0.004024,529.8540551,,2.54E-01,,0.259607298,
124,0.00108903,-0.00406643,-0.000706766,-0.00377878,0.00135806,124.007,-0.2524,-28974.1,,,0.00406643,535.2687973,,2.68E-01,,0.260778221,
125,0.00104209,-0.00411061,-0.000840375,-0.00382074,0.0012457,125.004,-0.2547,-29244.6,,,0.00411061,540.2660262,,2.54E-01,,0.248941595,
126,0.00116875,-0.00422058,-0.000644732,-0.00380293,0.00131366,126.009,-0.2567,-29505.5,,,0.00422058,545.0859043,,2.77E-01,,0.267497624,
127,0.00112395,-0.00417386,-0.00072145,-0.00384708,0.00139185,127.005,-0.2588,-29805,,,0.00417386,550.6188805,,2.69E-01,,0.239236558,
128,0.00107305,-0.00426478,-0.000822448,-0.00391767,0.00132222,128.004,-0.2609,-30082,,,0.00426478,555.7361907,,2.52E-01,,0.243469701,
129,0.00115574,-0.00424004,-0.000724574,-0.00396578,0.00140918,129.005,-0.263,-30362.2,,,0.00424004,560.9126178,,2.73E-01,,0.244863683,
130,0.0011337,-0.00431228,-0.000658149,-0.00396702,0.00137419,130.003,-0.2652,-30629.5,,,0.00431228,565.8507297,,2.63E-01,,0.246867233,
131,0.00114536,-0.00440242,-0.00071246,-0.00403632,0.00141734,131.006,-0.2674,-30954.8,,,0.00440242,571.8603362,,2.60E-01,,0.243713612,
132,0.00106124,-0.00433914,-0.000740045,-0.00399073,0.00140905,132.005,-0.2694,-31225.4,,,0.00433914,576.8594125,,2.45E-01,,0.263072412,
133,0.00116109,-0.00437322,-0.000797181,-0.00409099,0.00138601,133.004,-0.2714,-31524.9,,,0.00437322,582.3923887,,2.66E-01,,0.255531212,
134,0.00106805,-0.00441333,-0.000928585,-0.00411982,0.00142768,134.007,-0.2738,-31782.6,,,0.00441333,587.1531498,,2.42E-01,,0.258897728,
135,0.00111365,-0.00443906,-0.000800484,-0.00412922,0.00141077,135.003,-0.2757,-32104.7,,,0.00443906,593.1036394,,2.51E-01,,0.257858848,
136,0.00121258,-0.00449202,-0.000761365,-0.00414422,0.0014528,136.006,-0.2779,-32388.1,,,0.00449202,598.3391834,,2.70E-01,,0.283283497,
137,0.00115625,-0.00452677,-0.000855616,-0.00417471,0.00149734,137.004,-0.2799,-32671.5,,,0.00452677,603.5747275,,2.55E-01,,0.236528141,
138,0.00106268,-0.00461258,-0.000901807,-0.00425869,0.00150108,138.005,-0.282,-32971.1,,,0.00461258,609.1095511,,2.30E-01,,0.263848871,
139,0.00119153,-0.00458974,-0.000793027,-0.00432117,0.00153445,139.006,-0.2842,-33212.6,,,0.00458974,613.5710327,,2.60E-01,,0.247402937,
140,0.00121271,-0.00465035,-0.000777691,-0.0042987,0.00151168,140.002,-0.2863,-33531.5,,,0.00465035,619.4624053,,2.61E-01,,0.258095596,
141,0.00114427,-0.00459654,-0.000786815,-0.00428153,0.00152282,141.008,-0.2884,-33840.7,,,0.00459654,625.1745797,,2.49E-01,,0.254586341,
142,0.00124946,-0.00467092,-0.000800082,-0.00434054,0.00153672,142.002,-0.2904,-34101.6,,,0.00467092,629.9944578,,2.67E-01,,0.2727132,
143,0.00113451,-0.00474221,-0.000838627,-0.00438865,0.00152723,143.001,-0.2925,-34385,,,0.00474221,635.2300018,,2.39E-01,,0.25108616,
144,0.00115503,-0.00474404,-0.000844266,-0.00444032,0.00158621,144.005,-0.2947,-34674.9,,,0.00474404,640.5856272,,2.43E-01,,0.252604893,
145,0.00116489,-0.0047573,-0.00099964,-0.00447592,0.00150757,145.006,-0.2968,-34951.8,,,0.0047573,645.70109,,2.45E-01,,0.267321615,
146,0.00118695,-0.00480805,-0.000813238,-0.00449975,0.00153367,146.004,-0.299,-35232,,,0.00480805,650.8775171,,2.47E-01,,0.273777315,
147,0.0011679,-0.0047921,-0.000829156,-0.00447959,0.00156546,147.006,-0.3012,-35528.4,,,0.0047921,656.3532237,,2.44E-01,,0.269141493,
148,0.00128931,-0.00490097,-0.000840664,-0.00458523,0.00159538,148.003,-0.3031,-35827.9,,,0.00490097,661.8861999,,2.63E-01,,0.26235173,
149,0.00125497,-0.00491122,-0.000757509,-0.00459932,0.0015857,149.004,-0.3053,-36085.6,,,0.00491122,666.646961,,2.56E-01,,0.256686704,
150,0.00127707,-0.00493272,-0.000828392,-0.00460947,0.00159442,150.004,-0.3072,-36385.1,,,0.00493272,672.1799372,,2.59E-01,,0.24952566,
151,0.00128612,-0.00498769,-0.000791003,-0.00466405,0.00163012,151.004,-0.3095,-36732.9,,,0.00498769,678.6052097,,2.58E-01,,0.255571213,
152,0.00140497,-0.00495959,-0.000808085,-0.004651,0.00172502,152.004,-0.3115,-36948.7,,,0.00495959,682.5919084,,2.83E-01,,0.259655104,
153,0.0012028,-0.00508523,-0.0010044,-0.00476663,0.00169722,153.003,-0.3137,-37257.9,,,0.00508523,688.3040828,,2.37E-01,,0.252685273,
154,0.00133788,-0.00507063,-0.0008762,-0.00474871,0.00166896,154.005,-0.3159,-37534.9,,,0.00507063,693.4213929,,2.64E-01,,0.238878595,
155,0.00125699,-0.00508074,-0.000914883,-0.00477522,0.00166118,155.004,-0.3179,-37837.7,,,0.00508074,699.0153335,,2.47E-01,,0.26272364,
156,0.00132601,-0.00513767,-0.000789713,-0.00484367,0.00167446,156.006,-0.3201,-38121.1,,,0.00513767,704.2508775,,2.58E-01,,0.242256455,
157,0.001311,-0.00514953,-0.000867795,-0.00479163,0.00171244,157.003,-0.3221,-38394.9,,,0.00514953,709.3090708,,2.55E-01,,0.252024207,
158,0.00140933,-0.00516781,-0.000803252,-0.00483488,0.00170421,158.008,-0.3243,-38684.7,,,0.00516781,714.6628487,,2.73E-01,,0.239727985,
159,0.00130148,-0.0051834,-0.00100889,-0.00488191,0.00170313,159.006,-0.3263,-38964.9,,,0.0051834,719.8392758,,2.51E-01,,0.258576302,
160,0.00132223,-0.00523438,-0.000829503,-0.00494061,0.00173708,160.004,-0.3285,-39261.3,,,0.00523438,725.3149824,,2.53E-01,,0.24216024,
161,0.00142746,-0.00533986,-0.00085912,-0.00500842,0.00175342,161.003,-0.3306,-39557.6,,,0.00533986,730.7888417,,2.67E-01,,0.243345024,
162,0.00145511,-0.00531494,-0.000896178,-0.00501259,0.00172121,162.005,-0.3327,-39828.1,,,0.00531494,735.7860706,,2.74E-01,,0.258748354,
163,0.00145633,-0.00541102,-0.000835311,-0.00503863,0.00170197,163.002,-0.3348,-40108.3,,,0.00541102,740.9624977,,2.69E-01,,0.254368347,
164,0.00140912,-0.00537111,-0.000795299,-0.00508441,0.00171248,164.005,-0.3369,-40395,,,0.00537111,746.2590061,,2.62E-01,,0.24722225,
165,0.00138397,-0.00539167,-0.000857505,-0.00510635,0.00177347,165.005,-0.3391,-40710.6,,,0.00539167,752.0894144,,2.57E-01,,0.256519444,
166,0.00136115,-0.00545495,-0.000919591,-0.00512862,0.00179212,166.006,-0.3411,-41003.7,,,0.00545495,757.5041567,,2.50E-01,,0.242966313,
167,0.00138928,-0.00543598,-0.000992511,-0.00515221,0.00179371,167.001,-0.3433,-41271,,,0.00543598,762.4422686,,2.56E-01,,0.244821342,
168,0.00143945,-0.0055437,-0.000953013,-0.0052137,0.00177474,168.005,-0.3452,-41560.9,,,0.0055437,767.797894,,2.60E-01,,0.243977836,
169,0.00140586,-0.00556368,-0.000999723,-0.00524244,0.00180096,169.003,-0.3475,-41857.2,,,0.00556368,773.2717532,,2.53E-01,,0.241769154,
170,0.00135104,-0.00565576,-0.00108024,-0.00531028,0.00175407,170.007,-0.3497,-42160,,,0.00565576,778.8656937,,2.39E-01,,0.269334153,
171,0.00149562,-0.00569275,-0.000878279,-0.00536098,0.00186148,171.008,-0.3518,-42443.4,,,0.00569275,784.1012378,,2.63E-01,,0.255813269,
172,0.00136989,-0.00565471,-0.00101878,-0.00532623,0.00187695,172.003,-0.3538,-42717.2,,,0.00565471,789.159431,,2.42E-01,,0.265747074,
173,0.00144177,-0.00572076,-0.000928752,-0.00537943,0.00180987,173.005,-0.356,-43016.7,,,0.00572076,794.6924072,,2.52E-01,,0.257335997,
174,0.001384,-0.00577321,-0.00100379,-0.00545388,0.00182845,174.007,-0.358,-43284,,,0.00577321,799.6305191,,2.40E-01,,0.251934111,
175,0.00149552,-0.00578367,-0.000955928,-0.00547107,0.00186861,175.006,-0.3601,-43577.1,,,0.00578367,805.0452614,,2.59E-01,,0.242488274,
176,0.00140258,-0.00579195,-0.000938183,-0.00552339,0.00183948,176.005,-0.3623,-43889.5,,,0.00579195,810.8165527,,2.42E-01,,0.260224145,
177,0.00142031,-0.00583661,-0.00106982,-0.00552175,0.00193552,177.007,-0.3644,-44153.6,,,0.00583661,815.6955478,,2.43E-01,,0.253596352,
178,0.00150472,-0.00581538,-0.000962652,-0.00551156,0.00187576,178.004,-0.3667,-44437.1,,,0.00581538,820.9329392,,2.59E-01,,0.24385919,
179,0.00150204,-0.00590498,-0.0010583,-0.00558747,0.00191709,179.003,-0.3685,-44720.5,,,0.00590498,826.1684833,,2.54E-01,,0.244028862,
180,0.00145917,-0.00590226,-0.00101758,-0.0055716,0.00194455,180.004,-0.3708,-45045.8,,,0.00590226,832.1780898,,2.47E-01,,0.251659632,
181,0.00152587,-0.00594836,-0.0010108,-0.00562995,0.00190701,181.005,-0.3728,-45303.5,,,0.00594836,836.9388509,,2.57E-01,,0.255060428,
182,0.00145902,-0.00600503,-0.00109977,-0.0056605,0.00193059,182.003,-0.375,-45606.2,,,0.00600503,842.530944,,2.43E-01,,0.233765464,
183,0.0014751,-0.00602521,-0.000995137,-0.00569693,0.00195049,183.003,-0.377,-45870.3,,,0.00602521,847.409939,,2.45E-01,,0.247685217,
184,0.00149089,-0.00611076,-0.000983709,-0.00568589,0.00196394,184.004,-0.3792,-46157,,,0.00611076,852.7064474,,2.44E-01,,0.244497308,
185,0.0014852,-0.00614305,-0.000993769,-0.00577354,0.00187669,185.005,-0.3813,-46482.3,,,0.00614305,858.7160539,,2.42E-01,,0.265785134,
186,0.00163826,-0.00608263,-0.000882095,-0.00580044,0.00193325,186.002,-0.3835,-46743.2,,,0.00608263,863.535932,,2.69E-01,,0.260609394,
187,0.00156559,-0.00612005,-0.000985764,-0.00583404,0.00201691,187.004,-0.3854,-47045.9,,,0.00612005,869.1280251,,2.56E-01,,0.244892545,
188,0.00164528,-0.00619115,-0.000987466,-0.00587722,0.00202884,188.006,-0.3876,-47339,,,0.00619115,874.5427674,,2.66E-01,,0.255671512,
189,0.00159353,-0.00619241,-0.00101626,-0.00593387,0.00201138,189.003,-0.3897,-47619.2,,,0.00619241,879.7191945,,2.57E-01,,0.25210968,
190,0.00157808,-0.00626386,-0.00094764,-0.00593307,0.00199671,190.006,-0.3917,-47912.3,,,0.00626386,885.1339368,,2.52E-01,,0.248357092,
191,0.00152513,-0.0062895,-0.00110982,-0.00599387,0.00199852,191.007,-0.394,-48208.6,,,0.0062895,890.607796,,2.42E-01,,0.256406566,
192,0.00163255,-0.00627363,-0.000878369,-0.00598536,0.00203772,192.005,-0.396,-48504.9,,,0.00627363,896.0816553,,2.60E-01,,0.251336385,
193,0.0016229,-0.00639954,-0.00105966,-0.00609089,0.00203178,193.004,-0.3983,-48775.5,,,0.00639954,901.0807316,,2.54E-01,,0.253798963,
194,0.00155539,-0.00637823,-0.00104501,-0.00611172,0.00200135,194.003,-0.4002,-49023.5,,,0.00637823,905.6622945,,2.44E-01,,0.250125442,
195,0.00157434,-0.00645145,-0.00112761,-0.00610031,0.0021049,195.002,-0.4024,-49335.9,,,0.00645145,911.4335858,,2.44E-01,,0.257727756,
196,0.00162781,-0.0064683,-0.00108488,-0.00612781,0.00209192,196.004,-0.4045,-49616.1,,,0.0064683,916.6100129,,2.52E-01,,0.251792285,
197,0.00164868,-0.00646388,-0.00104053,-0.00614714,0.0020243,197.004,-0.4066,-49915.6,,,0.00646388,922.1429891,,2.55E-01,,0.253101691,
198,0.00153759,-0.00657749,-0.00111261,-0.00623634,0.00205051,198.006,-0.4088,-50179.7,,,0.00657749,927.0219841,,2.34E-01,,0.247558645,
199,0.00162027,-0.00654165,-0.00113069,-0.00617235,0.00213464,199.006,-0.4108,-50488.9,,,0.00654165,932.7341585,,2.48E-01,,0.257014974,
200,0.00161467,-0.00660404,-0.00113813,-0.00628433,0.00209941,200.005,-0.4128,-50782,,,0.00660404,938.1489008,,2.44E-01,,0.255928475,
201,0.00174068,-0.0065492,-0.00110904,-0.00624772,0.0021335,201.004,-0.415,-51039.7,,,0.0065492,942.9096619,,2.66E-01,,0.254601071,
202,0.00171549,-0.00658261,-0.00105016,-0.00627498,0.00212118,202.005,-0.4171,-51329.6,,,0.00658261,948.2652873,,2.61E-01,,0.251840508,
203,0.00164318,-0.0067098,-0.0011939,-0.00639477,0.00212419,203.004,-0.4193,-51632.3,,,0.0067098,953.8573804,,2.45E-01,,0.254632665,
204,0.0016985,-0.00664329,-0.00105384,-0.00635973,0.00212399,204.003,-0.4214,-51931.9,,,0.00664329,959.392204,,2.56E-01,,0.256337605,
205,0.0017017,-0.00674984,-0.0010598,-0.00644889,0.00211192,205.002,-0.4234,-52183.1,,,0.00674984,964.0328838,,2.52E-01,,0.251665435,
206,0.0016776,-0.00675479,-0.0011116,-0.00643626,0.0021157,206.001,-0.4257,-52463.3,,,0.00675479,969.2093109,,2.48E-01,,0.251908856,
207,0.00174568,-0.00680825,-0.00109955,-0.00646541,0.00223237,207.001,-0.4278,-52769.3,,,0.00680825,974.8623684,,2.56E-01,,0.249860756,
208,0.00172838,-0.00687676,-0.00112187,-0.0064925,0.00215615,208.002,-0.4297,-53043,,,0.00687676,979.9187142,,2.51E-01,,0.259931266,
209,0.00174334,-0.00686898,-0.00104118,-0.00650536,0.00218084,209.005,-0.432,-53326.5,,,0.00686898,985.1561057,,2.54E-01,,0.247252429,
210,0.00174969,-0.00699525,-0.00118315,-0.0065641,0.00216418,210.004,-0.4339,-53626,,,0.00699525,990.6890818,,2.50E-01,,0.256284009,
211,0.00178269,-0.00691695,-0.0010389,-0.00659945,0.00221903,211.005,-0.4362,-53899.8,,,0.00691695,995.7472751,,2.58E-01,,0.249085374,
212,0.00176346,-0.00700363,-0.0010288,-0.00664242,0.00224824,212.001,-0.4383,-54199.3,,,0.00700363,1001.280251,,2.52E-01,,0.251804763,
213,0.00176177,-0.00696072,-0.0011955,-0.00665178,0.00225771,213.005,-0.4403,-54473.1,,,0.00696072,1006.338444,,2.53E-01,,0.255566242,
214,0.00175806,-0.00710159,-0.00117283,-0.00673375,0.00219477,214.005,-0.4424,-54762.9,,,0.00710159,1011.692222,,2.48E-01,,0.257972516,
215,0.00181166,-0.00704885,-0.00111783,-0.00674451,0.00220926,215.006,-0.4447,-55062.5,,,0.00704885,1017.227046,,2.57E-01,,0.248669983,
216,0.00182056,-0.00711355,-0.00111755,-0.00672601,0.00218385,216.004,-0.4467,-55333,,,0.00711355,1022.224275,,2.56E-01,,0.248962313,
217,0.00180448,-0.00708748,-0.0010878,-0.00675447,0.00232979,217.003,-0.4488,-55635.8,,,0.00708748,1027.818215,,2.55E-01,,0.25372567,
218,0.00180071,-0.0071502,-0.00102819,-0.00683536,0.00230265,218.005,-0.4508,-55887,,,0.0071502,1032.458895,,2.52E-01,,0.248114267,
219,0.00184104,-0.00723018,-0.00108357,-0.00691297,0.00224018,219.003,-0.4531,-56176.9,,,0.00723018,1037.814521,,2.55E-01,,0.252815765,
220,0.00186097,-0.00725984,-0.00100096,-0.00690634,0.00233858,220.007,-0.4552,-56470,,,0.00725984,1043.229263,,2.56E-01,,0.254244951,
221,0.00183562,-0.00729389,-0.00107816,-0.00695232,0.00230746,221.005,-0.4572,-56727.6,,,0.00729389,1047.988177,,2.52E-01,,0.25293703,
222,0.00184162,-0.00731066,-0.00115687,-0.00697304,0.0022898,222.005,-0.4593,-57030.4,,,0.00731066,1053.582117,,2.52E-01,,0.249710324,
223,0.00182132,-0.00728934,-0.00116722,-0.00699021,0.00240421,223.006,-0.4614,-57297.7,,,0.00728934,1058.520229,,2.50E-01,,0.246906376,
224,0.00190749,-0.00733844,-0.00120842,-0.00700023,0.00234396,224.005,-0.4636,-57597.3,,,0.00733844,1064.055053,,2.60E-01,,0.255618124,
225,0.00183511,-0.00742201,-0.00103642,-0.00710483,0.00231795,225.006,-0.4654,-57864.6,,,0.00742201,1068.993165,,2.47E-01,,0.24951344,
226,0.00189572,-0.00739695,-0.00116293,-0.00713214,0.00236216,226.006,-0.4678,-58141.6,,,0.00739695,1074.110475,,2.56E-01,,0.257823312,
227,0.00186618,-0.00749213,-0.0011216,-0.00712635,0.00235033,227.001,-0.4698,-58418.6,,,0.00749213,1079.227785,,2.49E-01,,0.25677399,
228,0.00189576,-0.00752869,-0.00117015,-0.00717427,0.00234847,228.002,-0.4721,-58734.2,,,0.00752869,1085.058193,,2.52E-01,,0.256784291,
229,0.00192114,-0.00751719,-0.00121985,-0.00721831,0.00238429,229.007,-0.4741,-59001.5,,,0.00751719,1089.996305,,2.56E-01,,0.248875029,
230,0.00194745,-0.00754906,-0.00108927,-0.00726757,0.00232555,230.006,-0.4762,-59275.3,,,0.00754906,1095.054498,,2.58E-01,,0.248950845,
231,0.00188884,-0.00759577,-0.00120342,-0.00725615,0.00239824,231.004,-0.4784,-59536.2,,,0.00759577,1099.874377,,2.49E-01,,0.258819061,
232,0.00190137,-0.00763718,-0.00123157,-0.00726346,0.00237258,232.006,-0.4804,-59842.2,,,0.00763718,1105.527434,,2.49E-01,,0.247231296,
233,0.00194244,-0.00765567,-0.0012022,-0.00731888,0.00240776,233.002,-0.4827,-60119.2,,,0.00765567,1110.644744,,2.54E-01,,0.249557896,
234,0.00191079,-0.00770125,-0.00122773,-0.00737544,0.00237148,234.003,-0.4847,-60428.3,,,0.00770125,1116.355071,,2.48E-01,,0.251559337,
235,0.0019387,-0.00766843,-0.00118675,-0.00738426,0.00241218,235.005,-0.4869,-60698.9,,,0.00766843,1121.354147,,2.53E-01,,0.26184886,
236,0.00197394,-0.00776393,-0.00120569,-0.00740965,0.00248896,236.007,-0.4889,-60953.3,,,0.00776393,1126.053944,,2.54E-01,,0.249691346,
237,0.00196978,-0.00778763,-0.00123458,-0.00746686,0.00248389,237.006,-0.4908,-61240,,,0.00778763,1131.350453,,2.53E-01,,0.246854093,
238,0.00194604,-0.00779319,-0.00113597,-0.00747575,0.00245756,238.004,-0.4931,-61517,,,0.00779319,1136.467763,,2.50E-01,,0.251622569,
239,0.0019462,-0.00788234,-0.00117145,-0.00754623,0.00244507,239.004,-0.4953,-61784.3,,,0.00788234,1141.405875,,2.47E-01,,0.247280468,
240,0.00201503,-0.00788297,-0.00107751,-0.00749111,0.00246583,240.007,-0.4974,-62077.4,,,0.00788297,1146.820617,,2.56E-01,,0.246892828,
241,0.00196535,-0.00787673,-0.00126967,-0.00759693,0.00248367,241.008,-0.4993,-62367.3,,,0.00787673,1152.176242,,2.50E-01,,0.253366796,
242,0.00204367,-0.00792663,-0.00125587,-0.00760454,0.0024631,242.004,-0.5016,-62650.7,,,0.00792663,1157.411786,,2.58E-01,,0.253849038,
243,0.00204976,-0.00798274,-0.00125817,-0.00763895,0.00256929,243.001,-0.5038,-62943.8,,,0.00798274,1162.826529,,2.57E-01,,0.23833882,
244,0.00205553,-0.00800489,-0.00120029,-0.00772357,0.00255673,244.005,-0.5057,-63214.4,,,0.00800489,1167.825605,,2.57E-01,,0.252118055,
245,0.00200709,-0.00806465,-0.00123808,-0.00771628,0.00248966,245.007,-0.5078,-63488.1,,,0.00806465,1172.881951,,2.49E-01,,0.255675754,
246,0.00200982,-0.00807316,-0.00117488,-0.00772271,0.0024997,246.005,-0.51,-63771.6,,,0.00807316,1178.119342,,2.49E-01,,0.255798377,
247,0.00209183,-0.00808221,-0.00121182,-0.00775701,0.00256166,247.005,-0.5122,-64067.9,,,0.00808221,1183.593202,,2.59E-01,,0.264713807,
248,0.00201628,-0.00815544,-0.00124089,-0.00780252,0.00254586,248.003,-0.5144,-64354.5,,,0.00815544,1188.887863,,2.47E-01,,0.240054724,
249,0.00204623,-0.00819942,-0.00117718,-0.00784675,0.00260001,248.999,-0.5163,-64615.4,,,0.00819942,1193.707741,,2.50E-01,,0.26005567,
250,0.0020827,-0.00827916,-0.00114354,-0.00793167,0.00256851,250.005,-0.5185,-64895.6,,,0.00827916,1198.884168,,2.52E-01,,0.257101959,
251,0.0021714,-0.00829257,-0.00124579,-0.00791504,0.00259402,251.005,-0.5206,-65172.6,,,0.00829257,1204.001478,,2.62E-01,,0.246052176,
252,0.00207298,-0.00830217,-0.00126174,-0.00791618,0.00260148,252.001,-0.5227,-65443.2,,,0.00830217,1209.000554,,2.50E-01,,0.251923468,
253,0.00205332,-0.00831795,-0.00126663,-0.00798068,0.00259038,253.005,-0.5247,-65745.9,,,0.00831795,1214.592647,,2.47E-01,,0.248998649,
254,0.00209935,-0.00834325,-0.00128712,-0.00795053,0.00265658,254.005,-0.5269,-66029.4,,,0.00834325,1219.830039,,2.52E-01,,0.252891017,
255,0.00207474,-0.00839023,-0.00129391,-0.00801405,0.00269232,255.003,-0.5289,-66296.7,,,0.00839023,1224.768151,,2.47E-01,,0.251220197,
256,0.00208719,-0.00845383,-0.00131201,-0.00808299,0.00265085,256.005,-0.5311,-66599.4,,,0.00845383,1230.360244,,2.47E-01,,0.254821825,
257,0.00213215,-0.00841527,-0.0012383,-0.00806774,0.00263426,257.005,-0.5332,-66841,,,0.00841527,1234.823573,,2.53E-01,,0.247161213,
258,0.00215265,-0.00848004,-0.00136022,-0.00816267,0.00269519,258.006,-0.5353,-67147,,,0.00848004,1240.47663,,2.54E-01,,0.240165237,
259,0.00200774,-0.00842389,-0.00133462,-0.00814137,0.00258669,259.005,-0.5375,-67407.9,,,0.00842389,1245.296508,,2.38E-01,,0.245887132,
260,0.00215747,-0.00855738,-0.00134239,-0.00821974,0.00268935,260.005,-0.5395,-67691.3,,,0.00855738,1250.532052,,2.52E-01,,0.241489869,
261,0.00220629,-0.00862925,-0.00129934,-0.00819011,0.00270593,261.002,-0.5417,-67990.8,,,0.00862925,1256.065029,,2.56E-01,,0.243246897,
262,0.00220743,-0.00862957,-0.00130494,-0.00823899,0.00268791,262.005,-0.5437,-68226,,,0.00862957,1260.410124,,2.56E-01,,0.257103223,
263,0.00227935,-0.00861062,-0.0012914,-0.00824774,0.00282013,263.005,-0.546,-68515.8,,,0.00861062,1265.763902,,2.65E-01,,0.24679181,
264,0.00208452,-0.00868352,-0.00128929,-0.00829011,0.00272497,264.003,-0.5479,-68789.6,,,0.00868352,1270.822095,,2.40E-01,,0.248180459,
265,0.00227401,-0.00874432,-0.00127425,-0.00834454,0.00277163,265.007,-0.55,-69073,,,0.00874432,1276.057639,,2.60E-01,,0.246123679,
266,0.00224513,-0.00873245,-0.00137826,-0.00838686,0.00272802,266.004,-0.5523,-69324.3,,,0.00873245,1280.700166,,2.57E-01,,0.252776604,
267,0.00215539,-0.00875989,-0.00133099,-0.00838626,0.0027705,267.004,-0.5544,-69623.8,,,0.00875989,1286.233142,,2.46E-01,,0.255109532,
268,0.00222917,-0.0088486,-0.00133946,-0.00845241,0.00272453,268.004,-0.5565,-69904,,,0.0088486,1291.40957,,2.52E-01,,0.254900661,
269,0.00220999,-0.00887551,-0.00131398,-0.00852828,0.00275536,269.006,-0.5585,-70181,,,0.00887551,1296.52688,,2.49E-01,,0.255468785,
270,0.00224329,-0.00887058,-0.0013143,-0.00854808,0.00279813,270.005,-0.5606,-70458,,,0.00887058,1301.64419,,2.53E-01,,0.258879501,
271,0.00224672,-0.00894323,-0.00132024,-0.0085581,0.00277127,271.006,-0.5628,-70735,,,0.00894323,1306.7615,,2.51E-01,,0.257552731,
272,0.00227205,-0.00891623,-0.00134424,-0.0085976,0.00277705,272.007,-0.5649,-71018.4,,,0.00891623,1311.997044,,2.55E-01,,0.246636781,
273,0.00222649,-0.00900825,-0.00133574,-0.00861709,0.00276501,273.006,-0.5669,-71272.9,,,0.00900825,1316.698688,,2.47E-01,,0.259318839,
274,0.00216624,-0.00901979,-0.00132029,-0.00864776,0.00282431,274.004,-0.569,-71543.4,,,0.00901979,1321.695917,,2.40E-01,,0.250886249,
275,0.00220621,-0.00897245,-0.00131209,-0.00858825,0.00283031,275.004,-0.5712,-71823.6,,,0.00897245,1326.872344,,2.46E-01,,0.247991003,
276,0.00220083,-0.00911355,-0.00143875,-0.00867628,0.00278354,276.003,-0.5731,-72090.9,,,0.00911355,1331.810456,,2.41E-01,,0.2601095,
277,0.00221298,-0.00909767,-0.00140584,-0.00871724,0.00287134,277.004,-0.5754,-72355.1,,,0.00909767,1336.691299,,2.43E-01,,0.253293209,
278,0.0023631,-0.00919125,-0.00142937,-0.00877326,0.00284632,278.002,-0.5775,-72622.4,,,0.00919125,1341.629411,,2.57E-01,,0.251421801,
279,0.00226565,-0.00918041,-0.00144514,-0.00873586,0.00289052,279.005,-0.5797,-72909,,,0.00918041,1346.924072,,2.47E-01,,0.247220358,
280,0.0022867,-0.00921386,-0.00125873,-0.00877251,0.00291227,280.006,-0.5817,-73173.1,,,0.00921386,1351.803067,,2.48E-01,,0.244567096,
281,0.00227817,-0.0092562,-0.00147666,-0.00884768,0.00291119,281.004,-0.584,-73456.6,,,0.0092562,1357.040458,,2.46E-01,,0.253251067,
282,0.00233945,-0.00925501,-0.00126727,-0.00881405,0.0029114,282.003,-0.5859,-73711,,,0.00925501,1361.740255,,2.53E-01,,0.253009319,
283,0.00235948,-0.00924889,-0.00143644,-0.00888772,0.00295786,283.004,-0.5881,-73988,,,0.00924889,1366.857565,,2.55E-01,,0.251693265,
284,0.00238482,-0.00935588,-0.00129532,-0.0089769,0.00293377,284.004,-0.5903,-74248.9,,,0.00935588,1371.677443,,2.55E-01,,0.251449562,
285,0.0024018,-0.00940154,-0.00131665,-0.00894822,0.00289614,285.004,-0.5922,-74506.6,,,0.00940154,1376.438204,,2.55E-01,,0.258742412,
286,0.0024334,-0.00939974,-0.00139926,-0.00903926,0.00294428,286.004,-0.5945,-74796.4,,,0.00939974,1381.791982,,2.59E-01,,0.252759109,
287,0.00243359,-0.0094489,-0.00126692,-0.00908275,0.00294004,287.003,-0.5966,-75067,,,0.0094489,1386.791059,,2.58E-01,,0.248592499,
288,0.00234374,-0.0095028,-0.00143363,-0.00910583,0.00292394,288.005,-0.5987,-75334.3,,,0.0095028,1391.729171,,2.47E-01,,0.248234073,
289,0.00246641,-0.00951111,-0.00132415,-0.00910398,0.00291745,289.004,-0.6007,-75585.5,,,0.00951111,1396.36985,,2.59E-01,,0.258129118,
290,0.00240483,-0.00958534,-0.00134737,-0.00916111,0.00292923,290.003,-0.6029,-75846.4,,,0.00958534,1401.189728,,2.51E-01,,0.252764728,
291,0.00239042,-0.00963914,-0.00141331,-0.00920002,0.00293035,291.003,-0.6049,-76104.1,,,0.00963914,1405.95049,,2.48E-01,,0.246027164,
292,0.00249895,-0.0096073,-0.00134551,-0.00915462,0.00294861,292.002,-0.6071,-76394,,,0.0096073,1411.306115,,2.60E-01,,0.249545027,
293,0.00245355,-0.0096866,-0.00135192,-0.0092305,0.00301241,293.007,-0.6091,-76671,,,0.0096866,1416.423425,,2.53E-01,,0.249188304,
294,0.00242969,-0.0096638,-0.00149674,-0.00923374,0.00299697,294.008,-0.6115,-76931.9,,,0.0096638,1421.243303,,2.51E-01,,0.253774571,
295,0.00240515,-0.00972877,-0.00141852,-0.00932724,0.00294687,295.004,-0.6134,-77186.3,,,0.00972877,1425.9431,,2.47E-01,,0.24946491,
296,0.00239901,-0.00980921,-0.00134283,-0.00936023,0.00297525,296,-0.6155,-77444,,,0.00980921,1430.703861,,2.45E-01,,0.250599339,
297,0.00248163,-0.00979909,-0.00141494,-0.0093548,0.00306115,297.006,-0.6176,-77749.9,,,0.00979909,1436.355071,,2.53E-01,,0.245243145,
298,0.00249115,-0.00984608,-0.00145196,-0.00936387,0.00304455,298.004,-0.6196,-77998,,,0.00984608,1440.938481,,2.53E-01,,0.250963824,
299,0.00248458,-0.00987146,-0.0013732,-0.00942014,0.0030235,299.005,-0.622,-78258.8,,,0.00987146,1445.756512,,2.52E-01,,0.240435572,
300,0.00250051,-0.00994438,-0.00149089,-0.00946096,0.00303784,300.005,-0.6239,-78513.3,,,0.00994438,1450.458156,,2.51E-01,,0.253132281,
301,0.00257391,-0.00994777,-0.00144456,-0.00950437,0.00314038,301.006,-0.6262,-78803.2,,,0.00994777,1455.813782,,2.59E-01,,0.251377906,
302,0.00252085,-0.00997333,-0.00141123,-0.00948131,0.00304889,302.005,-0.628,-79060.8,,,0.00997333,1460.572695,,2.53E-01,,0.243797788,
303,0.00248239,-0.00998578,-0.00147399,-0.00955312,0.00305797,303.005,-0.6302,-79334.6,,,0.00998578,1465.630889,,2.49E-01,,0.253848854,
304,0.00248666,-0.0100174,-0.00157283,-0.00955578,0.00308808,304.004,-0.6324,-79608.4,,,0.0100174,1470.689082,,2.48E-01,,0.254547699,
305,0.00258173,-0.0100017,-0.00137402,-0.00956412,0.00312339,305.005,-0.6346,-79856.4,,,0.0100017,1475.270645,,2.58E-01,,0.253362141,
306,0.00254481,-0.0100679,-0.001519,-0.00960489,0.00313911,306.006,-0.6368,-80123.7,,,0.0100679,1480.208757,,2.53E-01,,0.260637132,
307,0.00248886,-0.0101162,-0.00149168,-0.00963337,0.00312301,307.005,-0.6386,-80397.5,,,0.0101162,1485.26695,,2.46E-01,,0.25232417,
308,0.00254496,-0.0101984,-0.00148062,-0.00971035,0.00312001,308.004,-0.6408,-80626.2,,,0.0101984,1489.491964,,2.50E-01,,0.257994694,
309,0.00255575,-0.0102563,-0.00140563,-0.00980698,0.00315016,309.006,-0.6429,-80912.8,,,0.0102563,1494.786625,,2.49E-01,,0.255637679,
310,0.00259888,-0.0102409,-0.00146535,-0.00979869,0.0032238,310.007,-0.645,-81202.7,,,0.0102409,1500.14225,,2.54E-01,,0.30317794,
311,0.00256183,-0.0102693,-0.00145012,-0.00983627,0.00319733,311.005,-0.647,-81441,,,0.0102693,1504.544615,,2.49E-01,,0.300389213,
312,0.00258611,-0.0103197,-0.00154994,-0.00984136,0.0031034,312.003,-0.6493,-81695.5,,,0.0103197,1509.246259,,2.51E-01,,0.303829965,
313,0.00254376,-0.0103724,-0.00150352,-0.00988658,0.00316254,313.003,-0.6514,-81949.9,,,0.0103724,1513.946056,,2.45E-01,,0.299967773,
314,0.00260774,-0.0103909,-0.00140781,-0.00989022,0.00317848,314.006,-0.6536,-82246.3,,,0.0103909,1519.421762,,2.51E-01,,0.299839208,
315,0.00251712,-0.010469,-0.00153086,-0.00996576,0.00312647,315.006,-0.6557,-82500.7,,,0.010469,1524.121559,,2.40E-01,,0.309221997,
316,0.00266161,-0.0105147,-0.00145428,-0.0100105,0.00318739,316.005,-0.6579,-82751.9,,,0.0105147,1528.762239,,2.53E-01,,0.304065847,
317,0.00263527,-0.0104833,-0.00136926,-0.0100181,0.00315364,317.006,-0.6597,-83006.4,,,0.0104833,1533.463883,,2.51E-01,,0.31393391,
318,0.00256997,-0.0105414,-0.00148002,-0.0100178,0.00311885,318.001,-0.6621,-83283.4,,,0.0105414,1538.581193,,2.44E-01,,0.300694275,
319,0.00267577,-0.0105408,-0.00148198,-0.0100582,0.00318819,319.005,-0.6641,-83515.3,,,0.0105408,1542.865324,,2.54E-01,,0.303212171,
320,0.0026811,-0.0105328,-0.00144423,-0.01012,0.00319001,320.004,-0.6661,-83827.7,,,0.0105328,1548.636616,,2.55E-01,,0.302821413,
321,0.00267368,-0.0105528,-0.00155535,-0.0101112,0.0032499,321.001,-0.6683,-84069.3,,,0.0105528,1553.099945,,2.53E-01,,0.300162309,
322,0.00278337,-0.0106791,-0.00140221,-0.010206,0.00330059,322.004,-0.6703,-84339.8,,,0.0106791,1558.097173,,2.61E-01,,0.301691339,
323,0.00270219,-0.0107092,-0.00142624,-0.0101886,0.00323752,323.004,-0.6726,-84603.9,,,0.0107092,1562.976168,,2.52E-01,,0.22083393,
324,0.00276173,-0.0107046,-0.00146499,-0.0102345,0.00327162,324.001,-0.6746,-84822.9,,,0.0107046,1567.021984,,2.58E-01,,0.233367826,
325,0.00274969,-0.0107562,-0.00154701,-0.0102609,0.00334628,325.004,-0.6764,-85096.7,,,0.0107562,1572.080177,,2.56E-01,,0.229373658,
326,0.00325889,-0.0107491,-0.00121451,-0.0103066,0.00332031,326.004,-0.6788,-85376.9,,,0.0107491,1577.256604,,3.03E-01,,,
327,0.00324922,-0.0108167,-0.00132116,-0.0102742,0.00335276,327.007,-0.6811,-85621.7,,,0.0108167,1581.77905,,3.00E-01,,,
328,0.00327711,-0.010786,-0.0013055,-0.0103492,0.00335617,328.004,-0.6831,-85869.7,,,0.010786,1586.360613,,3.04E-01,,,
329,0.00325777,-0.0108604,-0.00124427,-0.0104247,0.00335102,329.004,-0.6853,-86130.6,,,0.0108604,1591.180491,,3.00E-01,,,
330,0.00326333,-0.0108836,-0.00138427,-0.0104209,0.00328858,330.005,-0.6874,-86417.3,,,0.0108836,1596.477,,3.00E-01,,,
331,0.00339467,-0.0109781,-0.00131008,-0.0104864,0.00342764,331.003,-0.6894,-86655.6,,,0.0109781,1600.879364,,3.09E-01,,,
332,0.00334141,-0.0109891,-0.00131927,-0.0105163,0.00339434,332.007,-0.6915,-86910,,,0.0109891,1605.579161,,3.04E-01,,,
333,0.00344194,-0.0109639,-0.00130276,-0.0104784,0.00343677,333.008,-0.6938,-87151.6,,,0.0109639,1610.04249,,3.14E-01,,,
334,0.00333058,-0.0110763,-0.00135767,-0.0105714,0.00334269,334.004,-0.6958,-87406.1,,,0.0110763,1614.744134,,3.01E-01,,,
335,0.00336423,-0.0110953,-0.0012942,-0.0105973,0.00335402,335.004,-0.6979,-87686.3,,,0.0110953,1619.920562,,3.03E-01,,,
336,0.00336586,-0.011115,-0.00145659,-0.0106186,0.00342546,336.003,-0.7001,-87950.4,,,0.011115,1624.799557,,3.03E-01,,,
337,0.00336578,-0.0112132,-0.00124728,-0.0106738,0.00345877,337.004,-0.7021,-88214.5,,,0.0112132,1629.678552,,3.00E-01,,,
338,0.00337484,-0.0111864,-0.00129505,-0.0106722,0.00339698,338.004,-0.7042,-88472.2,,,0.0111864,1634.439313,,3.02E-01,,,
339,0.00246645,-0.0111688,-0.00040453,-0.011148,0.00343875,339.004,-0.7062,-88655.8,,,0.0111688,1637.831147,,2.21E-01,,,
340,0.00263862,-0.0113067,-0.000475719,-0.0112543,0.00349292,340.004,-0.7084,-88936,,,0.0113067,1643.007574,,2.33E-01,,,
341,0.00256348,-0.011176,-0.000480855,-0.0107759,0.00341878,341.007,-0.7106,-89161.4,,,0.011176,1647.171624,,2.29E-01,,,
342,0,0,0,,,342.006,-0.7107,35.4284,,,0,-0.654505819,,,,,
343,0,0,0,,,343.003,-0.7106,22.5454,,,0,-0.416504711,,,,,
344,0,0,0,,,344.006,-0.7107,48.3115,,,0,-0.892508775,,,,,
345,0,0,0,,,345.004,-0.7106,19.3246,,,0,-0.35700351,,,,,
346,0,0,0,,,346.005,-0.7106,38.6492,,,0,-0.71400702,,,,,
347,0,0,0,,,347.003,-0.7107,12.8831,,,0,-0.238002956,,,,,
348,0,0,0,,,348.005,-0.7107,3.2208,,,0,-0.059501201,,,,,
349,0,0,0,,,349.005,-0.7107,12.8831,,,0,-0.238002956,,,,,
350,0,0,0,,,350.005,-0.7106,0,,,0,0,,,,,
351,0,0,0,,,351.003,-0.7107,51.5323,,,0,-0.952009976,,,,,
352,0,0,0,,,352.006,-0.7106,-9.6623,,,0,0.178501755,,,,,
353,0,0,0,,,353.003,-0.7106,16.1038,,,0,-0.297502309,,,,,
354,0,0,0,,,354.002,-0.7107,6.4415,,,0,-0.119000554,,,,,
355,0,0,0,,,355.007,-0.7108,6.4415,,,0,-0.119000554,,,,,
356,0,0,0,,,356.004,-0.7107,12.8831,,,0,-0.238002956,,,,,
357,0,0,0,,,357.002,-0.7106,25.7661,,,0,-0.476004064,,,,,
358,0,0,0,,,358.004,-0.7106,3.2208,,,0,-0.059501201,,,,,
359,0,0,0,,,359.003,-0.7107,-9.6623,,,0,0.178501755,,,,,
360,0,0,0,,,360.003,-0.7105,9.6623,,,0,-0.178501755,,,,,
361,0,0,0,,,361.007,-0.6271,3.2208,,,0,-0.059501201,,,,,
362,0,0,0,,,362.006,0,-19.3246,,,0,0.35700351,,,,,
363,0,0,0,,,363.005,-0.0001,12.8831,,,0,-0.238002956,,,,,
364,0,0,0,,,364.007,0,19.3246,,,0,-0.35700351,,,,,
365,0,0,0,,,365.003,-0.0001,-19.3246,,,0,0.35700351,,,,,
366,0,0,0,,,366.004,-0.0001,-16.1039,,,0,0.297504157,,,,,
367,0,0,0,,,367.003,-0.0001,-9.6623,,,0,0.178501755,,,,,
368,0,0,0,,,368.004,-0.0001,-22.5454,,,0,0.416504711,,,,,
369,0,0,0,,,369.004,-0.0001,3.2208,,,0,-0.059501201,,,,,
370,0,0,0,,,370.006,-0.0001,22.5454,,,0,-0.416504711,,,,,
371,0,0,0,,,371.004,0,-32.2077,,,0,0.595006466,,,,,
372,0,0,0,,,372.007,-0.0001,-28.9869,,,0,0.535505265,,,,,
373,0,0,0,,,373.004,0.0001,3.2208,,,0,-0.059501201,,,,,
374,0,0,0,,,374.002,-0.0001,-28.9869,,,0,0.535505265,,,,,
375,0,0,0,,,375.004,-0.0001,9.6623,,,0,-0.178501755,,,,,
376,0,0,0,,,376.003,0,-35.4285,,,0,0.654507667,,,,,
377,0,0,0,,,377.004,0,-19.3246,,,0,0.35700351,,,,,
378,0,0,0,,,378.003,0,9.6623,,,0,-0.178501755,,,,,
379,0,0,0,,,379.005,0,-32.2077,,,0,0.595006466,,,,,